[2024-12-01T09:19:35.206+0000] {local_task_job_runner.py:123} INFO - ::group::Pre task execution logs
[2024-12-01T09:19:35.229+0000] {taskinstance.py:2613} INFO - Dependencies all met for dep_context=non-requeueable deps ti=<TaskInstance: data_pipeline_etl.upload_to_hdfs manual__2024-12-01T09:14:29.557858+00:00 [queued]>
[2024-12-01T09:19:35.244+0000] {taskinstance.py:2613} INFO - Dependencies all met for dep_context=requeueable deps ti=<TaskInstance: data_pipeline_etl.upload_to_hdfs manual__2024-12-01T09:14:29.557858+00:00 [queued]>
[2024-12-01T09:19:35.245+0000] {taskinstance.py:2866} INFO - Starting attempt 1 of 2
[2024-12-01T09:19:35.379+0000] {taskinstance.py:2889} INFO - Executing <Task(BashOperator): upload_to_hdfs> on 2024-12-01 09:14:29.557858+00:00
[2024-12-01T09:19:35.394+0000] {logging_mixin.py:190} WARNING - /home/***/.local/lib/python3.12/site-packages/***/task/task_runner/standard_task_runner.py:70 DeprecationWarning: This process (pid=1231) is multi-threaded, use of fork() may lead to deadlocks in the child.
[2024-12-01T09:19:35.399+0000] {standard_task_runner.py:72} INFO - Started process 1232 to run task
[2024-12-01T09:19:35.397+0000] {standard_task_runner.py:104} INFO - Running: ['***', 'tasks', 'run', 'data_pipeline_etl', 'upload_to_hdfs', 'manual__2024-12-01T09:14:29.557858+00:00', '--job-id', '8', '--raw', '--subdir', 'DAGS_FOLDER/etl_pipeline_auto.py', '--cfg-path', '/tmp/tmpbcosbegk']
[2024-12-01T09:19:35.402+0000] {standard_task_runner.py:105} INFO - Job 8: Subtask upload_to_hdfs
[2024-12-01T09:19:35.510+0000] {task_command.py:467} INFO - Running <TaskInstance: data_pipeline_etl.upload_to_hdfs manual__2024-12-01T09:14:29.557858+00:00 [running]> on host 34f18a5346c0
[2024-12-01T09:19:35.618+0000] {taskinstance.py:3132} INFO - Exporting env vars: AIRFLOW_CTX_DAG_OWNER='***' AIRFLOW_CTX_DAG_ID='data_pipeline_etl' AIRFLOW_CTX_TASK_ID='upload_to_hdfs' AIRFLOW_CTX_EXECUTION_DATE='2024-12-01T09:14:29.557858+00:00' AIRFLOW_CTX_TRY_NUMBER='1' AIRFLOW_CTX_DAG_RUN_ID='manual__2024-12-01T09:14:29.557858+00:00'
[2024-12-01T09:19:35.619+0000] {taskinstance.py:731} INFO - ::endgroup::
[2024-12-01T09:19:35.669+0000] {subprocess.py:78} INFO - Tmp dir root location: /tmp
[2024-12-01T09:19:35.671+0000] {subprocess.py:88} INFO - Running command: ['/usr/bin/bash', '-c', 'python /opt/***/data-pipeline-project/upload-to-hdfs/upload_to_hdfs.py']
[2024-12-01T09:19:35.688+0000] {subprocess.py:99} INFO - Output:
[2024-12-01T09:19:35.852+0000] {subprocess.py:106} INFO - Traceback (most recent call last):
[2024-12-01T09:19:35.852+0000] {subprocess.py:106} INFO -   File "/opt/***/data-pipeline-project/upload-to-hdfs/upload_to_hdfs.py", line 47, in <module>
[2024-12-01T09:19:35.853+0000] {subprocess.py:106} INFO -     upload_to_hdfs(local_directories["mans_category"], mans_category_path)
[2024-12-01T09:19:35.853+0000] {subprocess.py:106} INFO -   File "/opt/***/data-pipeline-project/upload-to-hdfs/upload_to_hdfs.py", line 19, in upload_to_hdfs
[2024-12-01T09:19:35.853+0000] {subprocess.py:106} INFO -     open(upload_log, 'w').close()  # 로그 파일이 없으면 생성
[2024-12-01T09:19:35.853+0000] {subprocess.py:106} INFO -     ^^^^^^^^^^^^^^^^^^^^^
[2024-12-01T09:19:35.854+0000] {subprocess.py:106} INFO - FileNotFoundError: [Errno 2] No such file or directory: '/opt/***/data-project/data-pipeline-project/upload_log.txt'
[2024-12-01T09:19:35.857+0000] {subprocess.py:110} INFO - Command exited with return code 1
[2024-12-01T09:19:35.867+0000] {taskinstance.py:3311} ERROR - Task failed with exception
Traceback (most recent call last):
  File "/home/airflow/.local/lib/python3.12/site-packages/airflow/models/taskinstance.py", line 762, in _execute_task
    result = _execute_callable(context=context, **execute_callable_kwargs)
             ^^^^^^^^^^^^^^^^^^^^^^^^^^^^^^^^^^^^^^^^^^^^^^^^^^^^^^^^^^^^^
  File "/home/airflow/.local/lib/python3.12/site-packages/airflow/models/taskinstance.py", line 733, in _execute_callable
    return ExecutionCallableRunner(
           ^^^^^^^^^^^^^^^^^^^^^^^^
  File "/home/airflow/.local/lib/python3.12/site-packages/airflow/utils/operator_helpers.py", line 252, in run
    return self.func(*args, **kwargs)
           ^^^^^^^^^^^^^^^^^^^^^^^^^^
  File "/home/airflow/.local/lib/python3.12/site-packages/airflow/models/baseoperator.py", line 417, in wrapper
    return func(self, *args, **kwargs)
           ^^^^^^^^^^^^^^^^^^^^^^^^^^^
  File "/home/airflow/.local/lib/python3.12/site-packages/airflow/operators/bash.py", line 276, in execute
    raise AirflowException(
airflow.exceptions.AirflowException: Bash command failed. The command returned a non-zero exit code 1.
[2024-12-01T09:19:35.874+0000] {taskinstance.py:1225} INFO - Marking task as UP_FOR_RETRY. dag_id=data_pipeline_etl, task_id=upload_to_hdfs, run_id=manual__2024-12-01T09:14:29.557858+00:00, execution_date=20241201T091429, start_date=20241201T091935, end_date=20241201T091935
[2024-12-01T09:19:35.882+0000] {taskinstance.py:340} INFO - ::group::Post task execution logs
[2024-12-01T09:19:35.883+0000] {standard_task_runner.py:124} ERROR - Failed to execute job 8 for task upload_to_hdfs (Bash command failed. The command returned a non-zero exit code 1.; 1232)
Traceback (most recent call last):
  File "/home/airflow/.local/lib/python3.12/site-packages/airflow/task/task_runner/standard_task_runner.py", line 117, in _start_by_fork
    ret = args.func(args, dag=self.dag)
          ^^^^^^^^^^^^^^^^^^^^^^^^^^^^^
  File "/home/airflow/.local/lib/python3.12/site-packages/airflow/cli/cli_config.py", line 49, in command
    return func(*args, **kwargs)
           ^^^^^^^^^^^^^^^^^^^^^
  File "/home/airflow/.local/lib/python3.12/site-packages/airflow/utils/cli.py", line 116, in wrapper
    return f(*args, **kwargs)
           ^^^^^^^^^^^^^^^^^^
  File "/home/airflow/.local/lib/python3.12/site-packages/airflow/cli/commands/task_command.py", line 483, in task_run
    task_return_code = _run_task_by_selected_method(args, _dag, ti)
                       ^^^^^^^^^^^^^^^^^^^^^^^^^^^^^^^^^^^^^^^^^^^^
  File "/home/airflow/.local/lib/python3.12/site-packages/airflow/cli/commands/task_command.py", line 256, in _run_task_by_selected_method
    return _run_raw_task(args, ti)
           ^^^^^^^^^^^^^^^^^^^^^^^
  File "/home/airflow/.local/lib/python3.12/site-packages/airflow/cli/commands/task_command.py", line 341, in _run_raw_task
    return ti._run_raw_task(
           ^^^^^^^^^^^^^^^^^
  File "/home/airflow/.local/lib/python3.12/site-packages/airflow/utils/session.py", line 97, in wrapper
    return func(*args, session=session, **kwargs)
           ^^^^^^^^^^^^^^^^^^^^^^^^^^^^^^^^^^^^^^
  File "/home/airflow/.local/lib/python3.12/site-packages/airflow/models/taskinstance.py", line 3005, in _run_raw_task
    return _run_raw_task(
           ^^^^^^^^^^^^^^
  File "/home/airflow/.local/lib/python3.12/site-packages/airflow/models/taskinstance.py", line 273, in _run_raw_task
    TaskInstance._execute_task_with_callbacks(
  File "/home/airflow/.local/lib/python3.12/site-packages/airflow/models/taskinstance.py", line 3159, in _execute_task_with_callbacks
    result = self._execute_task(context, task_orig)
             ^^^^^^^^^^^^^^^^^^^^^^^^^^^^^^^^^^^^^^
  File "/home/airflow/.local/lib/python3.12/site-packages/airflow/models/taskinstance.py", line 3183, in _execute_task
    return _execute_task(self, context, task_orig)
           ^^^^^^^^^^^^^^^^^^^^^^^^^^^^^^^^^^^^^^^
  File "/home/airflow/.local/lib/python3.12/site-packages/airflow/models/taskinstance.py", line 762, in _execute_task
    result = _execute_callable(context=context, **execute_callable_kwargs)
             ^^^^^^^^^^^^^^^^^^^^^^^^^^^^^^^^^^^^^^^^^^^^^^^^^^^^^^^^^^^^^
  File "/home/airflow/.local/lib/python3.12/site-packages/airflow/models/taskinstance.py", line 733, in _execute_callable
    return ExecutionCallableRunner(
           ^^^^^^^^^^^^^^^^^^^^^^^^
  File "/home/airflow/.local/lib/python3.12/site-packages/airflow/utils/operator_helpers.py", line 252, in run
    return self.func(*args, **kwargs)
           ^^^^^^^^^^^^^^^^^^^^^^^^^^
  File "/home/airflow/.local/lib/python3.12/site-packages/airflow/models/baseoperator.py", line 417, in wrapper
    return func(self, *args, **kwargs)
           ^^^^^^^^^^^^^^^^^^^^^^^^^^^
  File "/home/airflow/.local/lib/python3.12/site-packages/airflow/operators/bash.py", line 276, in execute
    raise AirflowException(
airflow.exceptions.AirflowException: Bash command failed. The command returned a non-zero exit code 1.
[2024-12-01T09:19:35.920+0000] {local_task_job_runner.py:266} INFO - Task exited with return code 1
[2024-12-01T09:19:35.931+0000] {taskinstance.py:3895} INFO - 0 downstream tasks scheduled from follow-on schedule check
[2024-12-01T09:19:35.932+0000] {local_task_job_runner.py:245} INFO - ::endgroup::
