[2024-11-24T04:31:21.108+0000] {local_task_job_runner.py:123} INFO - ::group::Pre task execution logs
[2024-11-24T04:31:21.117+0000] {taskinstance.py:2613} INFO - Dependencies all met for dep_context=non-requeueable deps ti=<TaskInstance: data_pipeline_etl.collect_data scheduled__2024-11-24T00:00:00+00:00 [queued]>
[2024-11-24T04:31:21.122+0000] {taskinstance.py:2613} INFO - Dependencies all met for dep_context=requeueable deps ti=<TaskInstance: data_pipeline_etl.collect_data scheduled__2024-11-24T00:00:00+00:00 [queued]>
[2024-11-24T04:31:21.122+0000] {taskinstance.py:2866} INFO - Starting attempt 2 of 2
[2024-11-24T04:31:21.128+0000] {taskinstance.py:2889} INFO - Executing <Task(BashOperator): collect_data> on 2024-11-24 00:00:00+00:00
[2024-11-24T04:31:21.130+0000] {standard_task_runner.py:72} INFO - Started process 39 to run task
[2024-11-24T04:31:21.132+0000] {standard_task_runner.py:104} INFO - Running: ['***', 'tasks', 'run', 'data_pipeline_etl', 'collect_data', 'scheduled__2024-11-24T00:00:00+00:00', '--job-id', '47', '--raw', '--subdir', 'DAGS_FOLDER/etl_pipeline_auto.py', '--cfg-path', '/tmp/tmpd6cf3vw8']
[2024-11-24T04:31:21.134+0000] {standard_task_runner.py:105} INFO - Job 47: Subtask collect_data
[2024-11-24T04:31:21.158+0000] {task_command.py:467} INFO - Running <TaskInstance: data_pipeline_etl.collect_data scheduled__2024-11-24T00:00:00+00:00 [running]> on host c6ae8df9a3c1
[2024-11-24T04:31:21.196+0000] {taskinstance.py:3132} INFO - Exporting env vars: AIRFLOW_CTX_DAG_OWNER='***' AIRFLOW_CTX_DAG_ID='data_pipeline_etl' AIRFLOW_CTX_TASK_ID='collect_data' AIRFLOW_CTX_EXECUTION_DATE='2024-11-24T00:00:00+00:00' AIRFLOW_CTX_TRY_NUMBER='2' AIRFLOW_CTX_DAG_RUN_ID='scheduled__2024-11-24T00:00:00+00:00'
[2024-11-24T04:31:21.197+0000] {taskinstance.py:731} INFO - ::endgroup::
[2024-11-24T04:31:21.208+0000] {subprocess.py:78} INFO - Tmp dir root location: /tmp
[2024-11-24T04:31:21.208+0000] {subprocess.py:88} INFO - Running command: ['/usr/bin/bash', '-c', 'python /opt/***/data-pipeline-project/product_data_scraper.py']
[2024-11-24T04:31:21.212+0000] {subprocess.py:99} INFO - Output:
[2024-11-24T04:48:31.488+0000] {job.py:229} INFO - Heartbeat recovered after 177.75 seconds
[2024-11-24T04:54:27.322+0000] {job.py:229} INFO - Heartbeat recovered after 330.66 seconds
[2024-11-24T05:06:13.141+0000] {job.py:229} INFO - Heartbeat recovered after 680.63 seconds
[2024-11-24T05:11:07.354+0000] {job.py:229} INFO - Heartbeat recovered after 268.98 seconds
[2024-11-24T05:13:22.751+0000] {job.py:229} INFO - Heartbeat recovered after 24.35 seconds
[2024-11-24T05:15:36.256+0000] {timeout.py:68} ERROR - Process timed out, PID: 39
[2024-11-24T05:15:36.263+0000] {subprocess.py:117} INFO - Sending SIGTERM signal to process group
[2024-11-24T05:15:36.296+0000] {taskinstance.py:3311} ERROR - Task failed with exception
Traceback (most recent call last):
  File "/home/airflow/.local/lib/python3.12/site-packages/airflow/models/taskinstance.py", line 762, in _execute_task
    result = _execute_callable(context=context, **execute_callable_kwargs)
             ^^^^^^^^^^^^^^^^^^^^^^^^^^^^^^^^^^^^^^^^^^^^^^^^^^^^^^^^^^^^^
  File "/home/airflow/.local/lib/python3.12/site-packages/airflow/models/taskinstance.py", line 733, in _execute_callable
    return ExecutionCallableRunner(
           ^^^^^^^^^^^^^^^^^^^^^^^^
  File "/home/airflow/.local/lib/python3.12/site-packages/airflow/utils/operator_helpers.py", line 252, in run
    return self.func(*args, **kwargs)
           ^^^^^^^^^^^^^^^^^^^^^^^^^^
  File "/home/airflow/.local/lib/python3.12/site-packages/airflow/models/baseoperator.py", line 417, in wrapper
    return func(self, *args, **kwargs)
           ^^^^^^^^^^^^^^^^^^^^^^^^^^^
  File "/home/airflow/.local/lib/python3.12/site-packages/airflow/operators/bash.py", line 257, in execute
    result = self._run_inline_command(bash_path=bash_path, env=env)
             ^^^^^^^^^^^^^^^^^^^^^^^^^^^^^^^^^^^^^^^^^^^^^^^^^^^^^^
  File "/home/airflow/.local/lib/python3.12/site-packages/airflow/operators/bash.py", line 284, in _run_inline_command
    return self.subprocess_hook.run_command(
           ^^^^^^^^^^^^^^^^^^^^^^^^^^^^^^^^^
  File "/home/airflow/.local/lib/python3.12/site-packages/airflow/hooks/subprocess.py", line 104, in run_command
    for raw_line in iter(self.sub_process.stdout.readline, b""):
                    ^^^^^^^^^^^^^^^^^^^^^^^^^^^^^^^^^^^^^^^^^^^
  File "/home/airflow/.local/lib/python3.12/site-packages/airflow/utils/timeout.py", line 69, in handle_timeout
    raise AirflowTaskTimeout(self.error_message)
airflow.exceptions.AirflowTaskTimeout: Timeout, PID: 39
[2024-11-24T05:15:36.303+0000] {taskinstance.py:1225} INFO - Marking task as FAILED. dag_id=data_pipeline_etl, task_id=collect_data, run_id=scheduled__2024-11-24T00:00:00+00:00, execution_date=20241124T000000, start_date=20241124T043121, end_date=20241124T051536
[2024-11-24T05:15:36.316+0000] {taskinstance.py:340} INFO - ::group::Post task execution logs
[2024-11-24T05:15:36.345+0000] {local_task_job_runner.py:266} INFO - Task exited with return code 2
[2024-11-24T05:15:36.367+0000] {taskinstance.py:3895} INFO - 0 downstream tasks scheduled from follow-on schedule check
[2024-11-24T05:15:36.370+0000] {local_task_job_runner.py:245} INFO - ::endgroup::
[2024-11-24T07:15:12.116+0000] {local_task_job_runner.py:123} INFO - ::group::Pre task execution logs
[2024-11-24T07:15:12.126+0000] {taskinstance.py:2613} INFO - Dependencies all met for dep_context=non-requeueable deps ti=<TaskInstance: data_pipeline_etl.collect_data scheduled__2024-11-24T00:00:00+00:00 [queued]>
[2024-11-24T07:15:12.132+0000] {taskinstance.py:2613} INFO - Dependencies all met for dep_context=requeueable deps ti=<TaskInstance: data_pipeline_etl.collect_data scheduled__2024-11-24T00:00:00+00:00 [queued]>
[2024-11-24T07:15:12.132+0000] {taskinstance.py:2866} INFO - Starting attempt 2 of 2
[2024-11-24T07:15:12.139+0000] {taskinstance.py:2889} INFO - Executing <Task(BashOperator): collect_data> on 2024-11-24 00:00:00+00:00
[2024-11-24T07:15:12.142+0000] {standard_task_runner.py:72} INFO - Started process 166 to run task
[2024-11-24T07:15:12.145+0000] {standard_task_runner.py:104} INFO - Running: ['***', 'tasks', 'run', 'data_pipeline_etl', 'collect_data', 'scheduled__2024-11-24T00:00:00+00:00', '--job-id', '4', '--raw', '--subdir', 'DAGS_FOLDER/etl_pipeline_auto.py', '--cfg-path', '/tmp/tmpuswa0n7i']
[2024-11-24T07:15:12.147+0000] {standard_task_runner.py:105} INFO - Job 4: Subtask collect_data
[2024-11-24T07:15:12.175+0000] {task_command.py:467} INFO - Running <TaskInstance: data_pipeline_etl.collect_data scheduled__2024-11-24T00:00:00+00:00 [running]> on host 39b93340fe6b
[2024-11-24T07:15:12.212+0000] {taskinstance.py:3132} INFO - Exporting env vars: AIRFLOW_CTX_DAG_OWNER='***' AIRFLOW_CTX_DAG_ID='data_pipeline_etl' AIRFLOW_CTX_TASK_ID='collect_data' AIRFLOW_CTX_EXECUTION_DATE='2024-11-24T00:00:00+00:00' AIRFLOW_CTX_TRY_NUMBER='2' AIRFLOW_CTX_DAG_RUN_ID='scheduled__2024-11-24T00:00:00+00:00'
[2024-11-24T07:15:12.213+0000] {taskinstance.py:731} INFO - ::endgroup::
[2024-11-24T07:15:12.227+0000] {subprocess.py:78} INFO - Tmp dir root location: /tmp
[2024-11-24T07:15:12.228+0000] {subprocess.py:88} INFO - Running command: ['/usr/bin/bash', '-c', 'python /opt/***/data-pipeline-project/product_data_scraper.py']
[2024-11-24T07:15:12.233+0000] {subprocess.py:99} INFO - Output:
[2024-11-24T07:21:59.405+0000] {local_task_job_runner.py:127} ERROR - Received SIGTERM. Terminating subprocesses
[2024-11-24T07:21:59.413+0000] {process_utils.py:132} INFO - Sending 15 to group 166. PIDs of all processes in the group: [168, 166]
[2024-11-24T07:21:59.414+0000] {process_utils.py:87} INFO - Sending the signal 15 to group 166
[2024-11-24T07:21:59.418+0000] {taskinstance.py:3093} ERROR - Received SIGTERM. Terminating subprocesses.
[2024-11-24T07:21:59.421+0000] {subprocess.py:117} INFO - Sending SIGTERM signal to process group
[2024-11-24T07:21:59.442+0000] {taskinstance.py:3311} ERROR - Task failed with exception
Traceback (most recent call last):
  File "/home/airflow/.local/lib/python3.12/site-packages/airflow/models/taskinstance.py", line 762, in _execute_task
    result = _execute_callable(context=context, **execute_callable_kwargs)
             ^^^^^^^^^^^^^^^^^^^^^^^^^^^^^^^^^^^^^^^^^^^^^^^^^^^^^^^^^^^^^
  File "/home/airflow/.local/lib/python3.12/site-packages/airflow/models/taskinstance.py", line 733, in _execute_callable
    return ExecutionCallableRunner(
           ^^^^^^^^^^^^^^^^^^^^^^^^
  File "/home/airflow/.local/lib/python3.12/site-packages/airflow/utils/operator_helpers.py", line 252, in run
    return self.func(*args, **kwargs)
           ^^^^^^^^^^^^^^^^^^^^^^^^^^
  File "/home/airflow/.local/lib/python3.12/site-packages/airflow/models/baseoperator.py", line 417, in wrapper
    return func(self, *args, **kwargs)
           ^^^^^^^^^^^^^^^^^^^^^^^^^^^
  File "/home/airflow/.local/lib/python3.12/site-packages/airflow/operators/bash.py", line 257, in execute
    result = self._run_inline_command(bash_path=bash_path, env=env)
             ^^^^^^^^^^^^^^^^^^^^^^^^^^^^^^^^^^^^^^^^^^^^^^^^^^^^^^
  File "/home/airflow/.local/lib/python3.12/site-packages/airflow/operators/bash.py", line 284, in _run_inline_command
    return self.subprocess_hook.run_command(
           ^^^^^^^^^^^^^^^^^^^^^^^^^^^^^^^^^
  File "/home/airflow/.local/lib/python3.12/site-packages/airflow/hooks/subprocess.py", line 104, in run_command
    for raw_line in iter(self.sub_process.stdout.readline, b""):
                    ^^^^^^^^^^^^^^^^^^^^^^^^^^^^^^^^^^^^^^^^^^^
  File "/home/airflow/.local/lib/python3.12/site-packages/airflow/models/taskinstance.py", line 3095, in signal_handler
    raise AirflowTaskTerminated("Task received SIGTERM signal")
airflow.exceptions.AirflowTaskTerminated: Task received SIGTERM signal
[2024-11-24T07:21:59.450+0000] {taskinstance.py:1225} INFO - Marking task as FAILED. dag_id=data_pipeline_etl, task_id=collect_data, run_id=scheduled__2024-11-24T00:00:00+00:00, execution_date=20241124T000000, start_date=20241124T071512, end_date=20241124T072159
[2024-11-24T07:21:59.465+0000] {taskinstance.py:340} INFO - ::group::Post task execution logs
[2024-11-24T07:21:59.514+0000] {process_utils.py:80} INFO - Process psutil.Process(pid=168, status='terminated', started='07:15:11') (168) terminated with exit code None
[2024-11-24T07:21:59.515+0000] {process_utils.py:80} INFO - Process psutil.Process(pid=166, status='terminated', exitcode=2, started='07:15:11') (166) terminated with exit code 2
[2024-11-24T07:21:59.515+0000] {local_task_job_runner.py:266} INFO - Task exited with return code 143
[2024-11-24T07:21:59.539+0000] {taskinstance.py:3895} INFO - 0 downstream tasks scheduled from follow-on schedule check
[2024-11-24T07:22:03.774+0000] {local_task_job_runner.py:123} INFO - ::group::Pre task execution logs
[2024-11-24T07:22:03.785+0000] {taskinstance.py:2603} INFO - Dependencies not met for <TaskInstance: data_pipeline_etl.collect_data scheduled__2024-11-24T00:00:00+00:00 [failed]>, dependency 'Task Instance State' FAILED: Task is in the 'failed' state.
[2024-11-24T07:22:03.786+0000] {local_task_job_runner.py:166} INFO - Task is not able to be run
