[2024-12-15T05:30:15.395+0000] {local_task_job_runner.py:123} INFO - ::group::Pre task execution logs
[2024-12-15T05:30:15.453+0000] {taskinstance.py:2613} INFO - Dependencies all met for dep_context=non-requeueable deps ti=<TaskInstance: data_pipeline_etl.collect_data scheduled__2024-12-14T04:00:00+00:00 [queued]>
[2024-12-15T05:30:15.481+0000] {taskinstance.py:2613} INFO - Dependencies all met for dep_context=requeueable deps ti=<TaskInstance: data_pipeline_etl.collect_data scheduled__2024-12-14T04:00:00+00:00 [queued]>
[2024-12-15T05:30:15.482+0000] {taskinstance.py:2866} INFO - Starting attempt 2 of 2
[2024-12-15T05:30:15.512+0000] {taskinstance.py:2889} INFO - Executing <Task(BashOperator): collect_data> on 2024-12-14 04:00:00+00:00
[2024-12-15T05:30:15.532+0000] {logging_mixin.py:190} WARNING - /home/***/.local/lib/python3.12/site-packages/***/task/task_runner/standard_task_runner.py:70 DeprecationWarning: This process (pid=2291) is multi-threaded, use of fork() may lead to deadlocks in the child.
[2024-12-15T05:30:15.534+0000] {standard_task_runner.py:72} INFO - Started process 2292 to run task
[2024-12-15T05:30:15.530+0000] {standard_task_runner.py:104} INFO - Running: ['***', 'tasks', 'run', 'data_pipeline_etl', 'collect_data', 'scheduled__2024-12-14T04:00:00+00:00', '--job-id', '62', '--raw', '--subdir', 'DAGS_FOLDER/etl_pipeline_auto.py', '--cfg-path', '/tmp/tmpnezk5j6x']
[2024-12-15T05:30:15.535+0000] {standard_task_runner.py:105} INFO - Job 62: Subtask collect_data
[2024-12-15T05:30:15.650+0000] {task_command.py:467} INFO - Running <TaskInstance: data_pipeline_etl.collect_data scheduled__2024-12-14T04:00:00+00:00 [running]> on host bea0c6fb71a7
[2024-12-15T05:30:15.852+0000] {taskinstance.py:3132} INFO - Exporting env vars: AIRFLOW_CTX_DAG_OWNER='***' AIRFLOW_CTX_DAG_ID='data_pipeline_etl' AIRFLOW_CTX_TASK_ID='collect_data' AIRFLOW_CTX_EXECUTION_DATE='2024-12-14T04:00:00+00:00' AIRFLOW_CTX_TRY_NUMBER='2' AIRFLOW_CTX_DAG_RUN_ID='scheduled__2024-12-14T04:00:00+00:00'
[2024-12-15T05:30:15.854+0000] {taskinstance.py:731} INFO - ::endgroup::
[2024-12-15T05:30:15.901+0000] {subprocess.py:78} INFO - Tmp dir root location: /tmp
[2024-12-15T05:30:15.904+0000] {subprocess.py:88} INFO - Running command: ['/usr/bin/bash', '-c', 'python /opt/***/data-pipeline-project/product_data_scraper.py']
[2024-12-15T05:30:15.929+0000] {subprocess.py:99} INFO - Output:
[2024-12-15T05:31:41.393+0000] {job.py:229} INFO - Heartbeat recovered after 14.28 seconds
[2024-12-15T05:31:57.986+0000] {job.py:229} INFO - Heartbeat recovered after 18.83 seconds
[2024-12-15T05:32:07.756+0000] {job.py:229} INFO - Heartbeat recovered after 11.83 seconds
[2024-12-15T06:30:15.934+0000] {timeout.py:68} ERROR - Process timed out, PID: 2292
[2024-12-15T06:30:15.944+0000] {subprocess.py:117} INFO - Sending SIGTERM signal to process group
[2024-12-15T06:30:15.999+0000] {taskinstance.py:3311} ERROR - Task failed with exception
Traceback (most recent call last):
  File "/home/airflow/.local/lib/python3.12/site-packages/airflow/models/taskinstance.py", line 762, in _execute_task
    result = _execute_callable(context=context, **execute_callable_kwargs)
             ^^^^^^^^^^^^^^^^^^^^^^^^^^^^^^^^^^^^^^^^^^^^^^^^^^^^^^^^^^^^^
  File "/home/airflow/.local/lib/python3.12/site-packages/airflow/models/taskinstance.py", line 733, in _execute_callable
    return ExecutionCallableRunner(
           ^^^^^^^^^^^^^^^^^^^^^^^^
  File "/home/airflow/.local/lib/python3.12/site-packages/airflow/utils/operator_helpers.py", line 252, in run
    return self.func(*args, **kwargs)
           ^^^^^^^^^^^^^^^^^^^^^^^^^^
  File "/home/airflow/.local/lib/python3.12/site-packages/airflow/models/baseoperator.py", line 417, in wrapper
    return func(self, *args, **kwargs)
           ^^^^^^^^^^^^^^^^^^^^^^^^^^^
  File "/home/airflow/.local/lib/python3.12/site-packages/airflow/operators/bash.py", line 257, in execute
    result = self._run_inline_command(bash_path=bash_path, env=env)
             ^^^^^^^^^^^^^^^^^^^^^^^^^^^^^^^^^^^^^^^^^^^^^^^^^^^^^^
  File "/home/airflow/.local/lib/python3.12/site-packages/airflow/operators/bash.py", line 284, in _run_inline_command
    return self.subprocess_hook.run_command(
           ^^^^^^^^^^^^^^^^^^^^^^^^^^^^^^^^^
  File "/home/airflow/.local/lib/python3.12/site-packages/airflow/hooks/subprocess.py", line 104, in run_command
    for raw_line in iter(self.sub_process.stdout.readline, b""):
                    ^^^^^^^^^^^^^^^^^^^^^^^^^^^^^^^^^^^^^^^^^^^
  File "/home/airflow/.local/lib/python3.12/site-packages/airflow/utils/timeout.py", line 69, in handle_timeout
    raise AirflowTaskTimeout(self.error_message)
airflow.exceptions.AirflowTaskTimeout: Timeout, PID: 2292
[2024-12-15T06:30:16.017+0000] {taskinstance.py:1225} INFO - Marking task as FAILED. dag_id=data_pipeline_etl, task_id=collect_data, run_id=scheduled__2024-12-14T04:00:00+00:00, execution_date=20241214T040000, start_date=20241215T053015, end_date=20241215T063016
[2024-12-15T06:30:16.048+0000] {taskinstance.py:340} INFO - ::group::Post task execution logs
[2024-12-15T06:30:16.077+0000] {local_task_job_runner.py:266} INFO - Task exited with return code 2
[2024-12-15T06:30:16.112+0000] {taskinstance.py:3895} INFO - 0 downstream tasks scheduled from follow-on schedule check
[2024-12-15T06:30:16.113+0000] {local_task_job_runner.py:245} INFO - ::endgroup::
