[2024-12-19T00:10:32.994+0000] {local_task_job_runner.py:123} INFO - ::group::Pre task execution logs
[2024-12-19T00:10:33.055+0000] {taskinstance.py:2613} INFO - Dependencies all met for dep_context=non-requeueable deps ti=<TaskInstance: data_pipeline_etl.collect_data scheduled__2024-12-17T04:00:00+00:00 [queued]>
[2024-12-19T00:10:33.109+0000] {taskinstance.py:2613} INFO - Dependencies all met for dep_context=requeueable deps ti=<TaskInstance: data_pipeline_etl.collect_data scheduled__2024-12-17T04:00:00+00:00 [queued]>
[2024-12-19T00:10:33.112+0000] {taskinstance.py:2866} INFO - Starting attempt 1 of 2
[2024-12-19T00:10:33.145+0000] {taskinstance.py:2889} INFO - Executing <Task(BashOperator): collect_data> on 2024-12-17 04:00:00+00:00
[2024-12-19T00:10:33.155+0000] {logging_mixin.py:190} WARNING - /home/***/.local/lib/python3.12/site-packages/***/task/task_runner/standard_task_runner.py:70 DeprecationWarning: This process (pid=171) is multi-threaded, use of fork() may lead to deadlocks in the child.
[2024-12-19T00:10:33.157+0000] {standard_task_runner.py:72} INFO - Started process 174 to run task
[2024-12-19T00:10:33.159+0000] {standard_task_runner.py:104} INFO - Running: ['***', 'tasks', 'run', 'data_pipeline_etl', 'collect_data', 'scheduled__2024-12-17T04:00:00+00:00', '--job-id', '78', '--raw', '--subdir', 'DAGS_FOLDER/etl_pipeline_auto.py', '--cfg-path', '/tmp/tmpzjouw16n']
[2024-12-19T00:10:33.162+0000] {standard_task_runner.py:105} INFO - Job 78: Subtask collect_data
[2024-12-19T00:10:33.218+0000] {task_command.py:467} INFO - Running <TaskInstance: data_pipeline_etl.collect_data scheduled__2024-12-17T04:00:00+00:00 [running]> on host fef9ca937039
[2024-12-19T00:10:33.334+0000] {taskinstance.py:3132} INFO - Exporting env vars: AIRFLOW_CTX_DAG_OWNER='***' AIRFLOW_CTX_DAG_ID='data_pipeline_etl' AIRFLOW_CTX_TASK_ID='collect_data' AIRFLOW_CTX_EXECUTION_DATE='2024-12-17T04:00:00+00:00' AIRFLOW_CTX_TRY_NUMBER='1' AIRFLOW_CTX_DAG_RUN_ID='scheduled__2024-12-17T04:00:00+00:00'
[2024-12-19T00:10:33.335+0000] {taskinstance.py:731} INFO - ::endgroup::
[2024-12-19T00:10:33.403+0000] {subprocess.py:78} INFO - Tmp dir root location: /tmp
[2024-12-19T00:10:33.403+0000] {subprocess.py:88} INFO - Running command: ['/usr/bin/bash', '-c', 'python /opt/***/data-pipeline-project/product_data_scraper.py']
[2024-12-19T00:10:33.412+0000] {subprocess.py:99} INFO - Output:
[2024-12-19T00:18:36.880+0000] {local_task_job_runner.py:127} ERROR - Received SIGTERM. Terminating subprocesses
[2024-12-19T00:18:36.932+0000] {process_utils.py:132} INFO - Sending 15 to group 174. PIDs of all processes in the group: [176, 174]
[2024-12-19T00:18:36.948+0000] {process_utils.py:87} INFO - Sending the signal 15 to group 174
[2024-12-19T00:18:36.959+0000] {taskinstance.py:3093} ERROR - Received SIGTERM. Terminating subprocesses.
[2024-12-19T00:18:36.979+0000] {subprocess.py:117} INFO - Sending SIGTERM signal to process group
[2024-12-19T00:18:37.091+0000] {taskinstance.py:3311} ERROR - Task failed with exception
Traceback (most recent call last):
  File "/home/airflow/.local/lib/python3.12/site-packages/airflow/models/taskinstance.py", line 762, in _execute_task
    result = _execute_callable(context=context, **execute_callable_kwargs)
             ^^^^^^^^^^^^^^^^^^^^^^^^^^^^^^^^^^^^^^^^^^^^^^^^^^^^^^^^^^^^^
  File "/home/airflow/.local/lib/python3.12/site-packages/airflow/models/taskinstance.py", line 733, in _execute_callable
    return ExecutionCallableRunner(
           ^^^^^^^^^^^^^^^^^^^^^^^^
  File "/home/airflow/.local/lib/python3.12/site-packages/airflow/utils/operator_helpers.py", line 252, in run
    return self.func(*args, **kwargs)
           ^^^^^^^^^^^^^^^^^^^^^^^^^^
  File "/home/airflow/.local/lib/python3.12/site-packages/airflow/models/baseoperator.py", line 417, in wrapper
    return func(self, *args, **kwargs)
           ^^^^^^^^^^^^^^^^^^^^^^^^^^^
  File "/home/airflow/.local/lib/python3.12/site-packages/airflow/operators/bash.py", line 257, in execute
    result = self._run_inline_command(bash_path=bash_path, env=env)
             ^^^^^^^^^^^^^^^^^^^^^^^^^^^^^^^^^^^^^^^^^^^^^^^^^^^^^^
  File "/home/airflow/.local/lib/python3.12/site-packages/airflow/operators/bash.py", line 284, in _run_inline_command
    return self.subprocess_hook.run_command(
           ^^^^^^^^^^^^^^^^^^^^^^^^^^^^^^^^^
  File "/home/airflow/.local/lib/python3.12/site-packages/airflow/hooks/subprocess.py", line 104, in run_command
    for raw_line in iter(self.sub_process.stdout.readline, b""):
                    ^^^^^^^^^^^^^^^^^^^^^^^^^^^^^^^^^^^^^^^^^^^
  File "/home/airflow/.local/lib/python3.12/site-packages/airflow/models/taskinstance.py", line 3095, in signal_handler
    raise AirflowTaskTerminated("Task received SIGTERM signal")
airflow.exceptions.AirflowTaskTerminated: Task received SIGTERM signal
[2024-12-19T00:18:37.144+0000] {taskinstance.py:1225} INFO - Marking task as UP_FOR_RETRY. dag_id=data_pipeline_etl, task_id=collect_data, run_id=scheduled__2024-12-17T04:00:00+00:00, execution_date=20241217T040000, start_date=20241219T001033, end_date=20241219T001837
[2024-12-19T00:18:37.226+0000] {taskinstance.py:340} INFO - ::group::Post task execution logs
[2024-12-19T00:18:37.262+0000] {process_utils.py:80} INFO - Process psutil.Process(pid=174, status='terminated', exitcode=2, started='00:10:32') (174) terminated with exit code 2
[2024-12-19T00:18:37.264+0000] {process_utils.py:80} INFO - Process psutil.Process(pid=176, status='terminated', started='00:10:32') (176) terminated with exit code None
[2024-12-19T00:18:37.265+0000] {local_task_job_runner.py:266} INFO - Task exited with return code 143
[2024-12-19T00:18:37.292+0000] {taskinstance.py:3895} INFO - 0 downstream tasks scheduled from follow-on schedule check
[2024-12-19T00:18:37.666+0000] {local_task_job_runner.py:245} INFO - ::endgroup::
