[2024-12-17T05:43:49.880+0000] {local_task_job_runner.py:123} INFO - ::group::Pre task execution logs
[2024-12-17T05:43:49.908+0000] {taskinstance.py:2613} INFO - Dependencies all met for dep_context=non-requeueable deps ti=<TaskInstance: data_pipeline_etl.collect_data scheduled__2024-12-15T04:00:00+00:00 [queued]>
[2024-12-17T05:43:49.930+0000] {taskinstance.py:2613} INFO - Dependencies all met for dep_context=requeueable deps ti=<TaskInstance: data_pipeline_etl.collect_data scheduled__2024-12-15T04:00:00+00:00 [queued]>
[2024-12-17T05:43:49.941+0000] {taskinstance.py:2866} INFO - Starting attempt 2 of 2
[2024-12-17T05:43:50.037+0000] {taskinstance.py:2889} INFO - Executing <Task(BashOperator): collect_data> on 2024-12-15 04:00:00+00:00
[2024-12-17T05:43:50.050+0000] {standard_task_runner.py:104} INFO - Running: ['***', 'tasks', 'run', 'data_pipeline_etl', 'collect_data', 'scheduled__2024-12-15T04:00:00+00:00', '--job-id', '72', '--raw', '--subdir', 'DAGS_FOLDER/etl_pipeline_auto.py', '--cfg-path', '/tmp/tmp8n3zfljf']
[2024-12-17T05:43:50.055+0000] {logging_mixin.py:190} WARNING - /home/***/.local/lib/python3.12/site-packages/***/task/task_runner/standard_task_runner.py:70 DeprecationWarning: This process (pid=171) is multi-threaded, use of fork() may lead to deadlocks in the child.
[2024-12-17T05:43:50.060+0000] {standard_task_runner.py:72} INFO - Started process 175 to run task
[2024-12-17T05:43:50.056+0000] {standard_task_runner.py:105} INFO - Job 72: Subtask collect_data
[2024-12-17T05:43:50.178+0000] {task_command.py:467} INFO - Running <TaskInstance: data_pipeline_etl.collect_data scheduled__2024-12-15T04:00:00+00:00 [running]> on host 0a7106e64cc7
[2024-12-17T05:43:50.493+0000] {taskinstance.py:3132} INFO - Exporting env vars: AIRFLOW_CTX_DAG_OWNER='***' AIRFLOW_CTX_DAG_ID='data_pipeline_etl' AIRFLOW_CTX_TASK_ID='collect_data' AIRFLOW_CTX_EXECUTION_DATE='2024-12-15T04:00:00+00:00' AIRFLOW_CTX_TRY_NUMBER='2' AIRFLOW_CTX_DAG_RUN_ID='scheduled__2024-12-15T04:00:00+00:00'
[2024-12-17T05:43:50.494+0000] {taskinstance.py:731} INFO - ::endgroup::
[2024-12-17T05:43:50.547+0000] {subprocess.py:78} INFO - Tmp dir root location: /tmp
[2024-12-17T05:43:50.553+0000] {subprocess.py:88} INFO - Running command: ['/usr/bin/bash', '-c', 'python /opt/***/data-pipeline-project/product_data_scraper.py']
[2024-12-17T05:43:50.576+0000] {subprocess.py:99} INFO - Output:
[2024-12-17T05:48:44.457+0000] {local_task_job_runner.py:127} ERROR - Received SIGTERM. Terminating subprocesses
[2024-12-17T05:48:44.528+0000] {process_utils.py:132} INFO - Sending 15 to group 175. PIDs of all processes in the group: [179, 175]
[2024-12-17T05:48:44.535+0000] {process_utils.py:87} INFO - Sending the signal 15 to group 175
[2024-12-17T05:48:44.557+0000] {taskinstance.py:3093} ERROR - Received SIGTERM. Terminating subprocesses.
[2024-12-17T05:48:44.596+0000] {subprocess.py:117} INFO - Sending SIGTERM signal to process group
[2024-12-17T05:48:44.735+0000] {taskinstance.py:3311} ERROR - Task failed with exception
Traceback (most recent call last):
  File "/home/airflow/.local/lib/python3.12/site-packages/airflow/models/taskinstance.py", line 762, in _execute_task
    result = _execute_callable(context=context, **execute_callable_kwargs)
             ^^^^^^^^^^^^^^^^^^^^^^^^^^^^^^^^^^^^^^^^^^^^^^^^^^^^^^^^^^^^^
  File "/home/airflow/.local/lib/python3.12/site-packages/airflow/models/taskinstance.py", line 733, in _execute_callable
    return ExecutionCallableRunner(
           ^^^^^^^^^^^^^^^^^^^^^^^^
  File "/home/airflow/.local/lib/python3.12/site-packages/airflow/utils/operator_helpers.py", line 252, in run
    return self.func(*args, **kwargs)
           ^^^^^^^^^^^^^^^^^^^^^^^^^^
  File "/home/airflow/.local/lib/python3.12/site-packages/airflow/models/baseoperator.py", line 417, in wrapper
    return func(self, *args, **kwargs)
           ^^^^^^^^^^^^^^^^^^^^^^^^^^^
  File "/home/airflow/.local/lib/python3.12/site-packages/airflow/operators/bash.py", line 257, in execute
    result = self._run_inline_command(bash_path=bash_path, env=env)
             ^^^^^^^^^^^^^^^^^^^^^^^^^^^^^^^^^^^^^^^^^^^^^^^^^^^^^^
  File "/home/airflow/.local/lib/python3.12/site-packages/airflow/operators/bash.py", line 284, in _run_inline_command
    return self.subprocess_hook.run_command(
           ^^^^^^^^^^^^^^^^^^^^^^^^^^^^^^^^^
  File "/home/airflow/.local/lib/python3.12/site-packages/airflow/hooks/subprocess.py", line 104, in run_command
    for raw_line in iter(self.sub_process.stdout.readline, b""):
                    ^^^^^^^^^^^^^^^^^^^^^^^^^^^^^^^^^^^^^^^^^^^
  File "/home/airflow/.local/lib/python3.12/site-packages/airflow/models/taskinstance.py", line 3095, in signal_handler
    raise AirflowTaskTerminated("Task received SIGTERM signal")
airflow.exceptions.AirflowTaskTerminated: Task received SIGTERM signal
[2024-12-17T05:48:44.799+0000] {taskinstance.py:1225} INFO - Marking task as FAILED. dag_id=data_pipeline_etl, task_id=collect_data, run_id=scheduled__2024-12-15T04:00:00+00:00, execution_date=20241215T040000, start_date=20241217T054349, end_date=20241217T054844
[2024-12-17T05:48:44.897+0000] {taskinstance.py:340} INFO - ::group::Post task execution logs
[2024-12-17T05:48:44.935+0000] {process_utils.py:80} INFO - Process psutil.Process(pid=179, status='terminated', started='05:43:50') (179) terminated with exit code None
[2024-12-17T05:48:44.938+0000] {process_utils.py:80} INFO - Process psutil.Process(pid=175, status='terminated', exitcode=2, started='05:43:49') (175) terminated with exit code 2
[2024-12-17T05:48:44.939+0000] {local_task_job_runner.py:266} INFO - Task exited with return code 143
[2024-12-17T05:48:44.981+0000] {taskinstance.py:3895} INFO - 0 downstream tasks scheduled from follow-on schedule check
[2024-12-17T05:48:45.584+0000] {local_task_job_runner.py:245} INFO - ::endgroup::
