[2024-11-24T13:44:19.706+0000] {local_task_job_runner.py:123} INFO - ::group::Pre task execution logs
[2024-11-24T13:44:19.717+0000] {taskinstance.py:2613} INFO - Dependencies all met for dep_context=non-requeueable deps ti=<TaskInstance: data_pipeline_etl.collect_data scheduled__2024-11-23T00:00:00+00:00 [queued]>
[2024-11-24T13:44:19.722+0000] {taskinstance.py:2613} INFO - Dependencies all met for dep_context=requeueable deps ti=<TaskInstance: data_pipeline_etl.collect_data scheduled__2024-11-23T00:00:00+00:00 [queued]>
[2024-11-24T13:44:19.722+0000] {taskinstance.py:2866} INFO - Starting attempt 1 of 2
[2024-11-24T13:44:19.729+0000] {taskinstance.py:2889} INFO - Executing <Task(BashOperator): collect_data> on 2024-11-23 00:00:00+00:00
[2024-11-24T13:44:19.733+0000] {logging_mixin.py:190} WARNING - /home/***/.local/lib/python3.12/site-packages/***/task/task_runner/standard_task_runner.py:70 DeprecationWarning: This process (pid=188) is multi-threaded, use of fork() may lead to deadlocks in the child.
[2024-11-24T13:44:19.734+0000] {standard_task_runner.py:72} INFO - Started process 189 to run task
[2024-11-24T13:44:19.734+0000] {standard_task_runner.py:104} INFO - Running: ['***', 'tasks', 'run', 'data_pipeline_etl', 'collect_data', 'scheduled__2024-11-23T00:00:00+00:00', '--job-id', '32', '--raw', '--subdir', 'DAGS_FOLDER/etl_pipeline_auto.py', '--cfg-path', '/tmp/tmp3oajmwk5']
[2024-11-24T13:44:19.736+0000] {standard_task_runner.py:105} INFO - Job 32: Subtask collect_data
[2024-11-24T13:44:19.774+0000] {task_command.py:467} INFO - Running <TaskInstance: data_pipeline_etl.collect_data scheduled__2024-11-23T00:00:00+00:00 [running]> on host 5a4d94803274
[2024-11-24T13:44:19.828+0000] {taskinstance.py:3132} INFO - Exporting env vars: AIRFLOW_CTX_DAG_OWNER='***' AIRFLOW_CTX_DAG_ID='data_pipeline_etl' AIRFLOW_CTX_TASK_ID='collect_data' AIRFLOW_CTX_EXECUTION_DATE='2024-11-23T00:00:00+00:00' AIRFLOW_CTX_TRY_NUMBER='1' AIRFLOW_CTX_DAG_RUN_ID='scheduled__2024-11-23T00:00:00+00:00'
[2024-11-24T13:44:19.828+0000] {taskinstance.py:731} INFO - ::endgroup::
[2024-11-24T13:44:19.860+0000] {subprocess.py:78} INFO - Tmp dir root location: /tmp
[2024-11-24T13:44:19.860+0000] {subprocess.py:88} INFO - Running command: ['/usr/bin/bash', '-c', 'python /opt/***/data-pipeline-project/product_data_scraper.py']
[2024-11-24T13:44:19.865+0000] {subprocess.py:99} INFO - Output:
[2024-11-24T13:47:11.100+0000] {local_task_job_runner.py:346} WARNING - State of this instance has been externally set to None. Terminating instance.
[2024-11-24T13:47:11.102+0000] {local_task_job_runner.py:245} INFO - ::endgroup::
[2024-11-24T13:47:11.104+0000] {process_utils.py:132} INFO - Sending 15 to group 189. PIDs of all processes in the group: [191, 189]
[2024-11-24T13:47:11.104+0000] {process_utils.py:87} INFO - Sending the signal 15 to group 189
[2024-11-24T13:47:11.105+0000] {taskinstance.py:3093} ERROR - Received SIGTERM. Terminating subprocesses.
[2024-11-24T13:47:11.107+0000] {subprocess.py:117} INFO - Sending SIGTERM signal to process group
[2024-11-24T13:47:11.129+0000] {taskinstance.py:3311} ERROR - Task failed with exception
Traceback (most recent call last):
  File "/home/airflow/.local/lib/python3.12/site-packages/airflow/models/taskinstance.py", line 762, in _execute_task
    result = _execute_callable(context=context, **execute_callable_kwargs)
             ^^^^^^^^^^^^^^^^^^^^^^^^^^^^^^^^^^^^^^^^^^^^^^^^^^^^^^^^^^^^^
  File "/home/airflow/.local/lib/python3.12/site-packages/airflow/models/taskinstance.py", line 733, in _execute_callable
    return ExecutionCallableRunner(
           ^^^^^^^^^^^^^^^^^^^^^^^^
  File "/home/airflow/.local/lib/python3.12/site-packages/airflow/utils/operator_helpers.py", line 252, in run
    return self.func(*args, **kwargs)
           ^^^^^^^^^^^^^^^^^^^^^^^^^^
  File "/home/airflow/.local/lib/python3.12/site-packages/airflow/models/baseoperator.py", line 417, in wrapper
    return func(self, *args, **kwargs)
           ^^^^^^^^^^^^^^^^^^^^^^^^^^^
  File "/home/airflow/.local/lib/python3.12/site-packages/airflow/operators/bash.py", line 257, in execute
    result = self._run_inline_command(bash_path=bash_path, env=env)
             ^^^^^^^^^^^^^^^^^^^^^^^^^^^^^^^^^^^^^^^^^^^^^^^^^^^^^^
  File "/home/airflow/.local/lib/python3.12/site-packages/airflow/operators/bash.py", line 284, in _run_inline_command
    return self.subprocess_hook.run_command(
           ^^^^^^^^^^^^^^^^^^^^^^^^^^^^^^^^^
  File "/home/airflow/.local/lib/python3.12/site-packages/airflow/hooks/subprocess.py", line 104, in run_command
    for raw_line in iter(self.sub_process.stdout.readline, b""):
                    ^^^^^^^^^^^^^^^^^^^^^^^^^^^^^^^^^^^^^^^^^^^
  File "/home/airflow/.local/lib/python3.12/site-packages/airflow/models/taskinstance.py", line 3095, in signal_handler
    raise AirflowTaskTerminated("Task received SIGTERM signal")
airflow.exceptions.AirflowTaskTerminated: Task received SIGTERM signal
[2024-11-24T13:47:11.135+0000] {taskinstance.py:1225} INFO - Marking task as UP_FOR_RETRY. dag_id=data_pipeline_etl, task_id=collect_data, run_id=scheduled__2024-11-23T00:00:00+00:00, execution_date=20241123T000000, start_date=20241124T134419, end_date=20241124T134711
[2024-11-24T13:47:11.147+0000] {taskinstance.py:340} INFO - ::group::Post task execution logs
[2024-11-24T13:47:11.148+0000] {standard_task_runner.py:124} ERROR - Failed to execute job 32 for task collect_data ((psycopg2.errors.ForeignKeyViolation) insert or update on table "task_fail" violates foreign key constraint "task_fail_ti_fkey"
DETAIL:  Key (dag_id, task_id, run_id, map_index)=(data_pipeline_etl, collect_data, scheduled__2024-11-23T00:00:00+00:00, -1) is not present in table "task_instance".

[SQL: INSERT INTO task_fail (task_id, dag_id, run_id, map_index, start_date, end_date, duration) VALUES (%(task_id)s, %(dag_id)s, %(run_id)s, %(map_index)s, %(start_date)s, %(end_date)s, %(duration)s) RETURNING task_fail.id]
[parameters: {'task_id': 'collect_data', 'dag_id': 'data_pipeline_etl', 'run_id': 'scheduled__2024-11-23T00:00:00+00:00', 'map_index': -1, 'start_date': datetime.datetime(2024, 11, 24, 13, 44, 19, 717411, tzinfo=Timezone('UTC')), 'end_date': datetime.datetime(2024, 11, 24, 13, 47, 11, 134062, tzinfo=Timezone('UTC')), 'duration': 171}]
(Background on this error at: https://sqlalche.me/e/14/gkpj); 189)
Traceback (most recent call last):
  File "/home/airflow/.local/lib/python3.12/site-packages/airflow/models/taskinstance.py", line 273, in _run_raw_task
    TaskInstance._execute_task_with_callbacks(
  File "/home/airflow/.local/lib/python3.12/site-packages/airflow/models/taskinstance.py", line 3159, in _execute_task_with_callbacks
    result = self._execute_task(context, task_orig)
             ^^^^^^^^^^^^^^^^^^^^^^^^^^^^^^^^^^^^^^
  File "/home/airflow/.local/lib/python3.12/site-packages/airflow/models/taskinstance.py", line 3183, in _execute_task
    return _execute_task(self, context, task_orig)
           ^^^^^^^^^^^^^^^^^^^^^^^^^^^^^^^^^^^^^^^
  File "/home/airflow/.local/lib/python3.12/site-packages/airflow/models/taskinstance.py", line 762, in _execute_task
    result = _execute_callable(context=context, **execute_callable_kwargs)
             ^^^^^^^^^^^^^^^^^^^^^^^^^^^^^^^^^^^^^^^^^^^^^^^^^^^^^^^^^^^^^
  File "/home/airflow/.local/lib/python3.12/site-packages/airflow/models/taskinstance.py", line 733, in _execute_callable
    return ExecutionCallableRunner(
           ^^^^^^^^^^^^^^^^^^^^^^^^
  File "/home/airflow/.local/lib/python3.12/site-packages/airflow/utils/operator_helpers.py", line 252, in run
    return self.func(*args, **kwargs)
           ^^^^^^^^^^^^^^^^^^^^^^^^^^
  File "/home/airflow/.local/lib/python3.12/site-packages/airflow/models/baseoperator.py", line 417, in wrapper
    return func(self, *args, **kwargs)
           ^^^^^^^^^^^^^^^^^^^^^^^^^^^
  File "/home/airflow/.local/lib/python3.12/site-packages/airflow/operators/bash.py", line 257, in execute
    result = self._run_inline_command(bash_path=bash_path, env=env)
             ^^^^^^^^^^^^^^^^^^^^^^^^^^^^^^^^^^^^^^^^^^^^^^^^^^^^^^
  File "/home/airflow/.local/lib/python3.12/site-packages/airflow/operators/bash.py", line 284, in _run_inline_command
    return self.subprocess_hook.run_command(
           ^^^^^^^^^^^^^^^^^^^^^^^^^^^^^^^^^
  File "/home/airflow/.local/lib/python3.12/site-packages/airflow/hooks/subprocess.py", line 104, in run_command
    for raw_line in iter(self.sub_process.stdout.readline, b""):
                    ^^^^^^^^^^^^^^^^^^^^^^^^^^^^^^^^^^^^^^^^^^^
  File "/home/airflow/.local/lib/python3.12/site-packages/airflow/models/taskinstance.py", line 3095, in signal_handler
    raise AirflowTaskTerminated("Task received SIGTERM signal")
airflow.exceptions.AirflowTaskTerminated: Task received SIGTERM signal

During handling of the above exception, another exception occurred:

Traceback (most recent call last):
  File "/home/airflow/.local/lib/python3.12/site-packages/sqlalchemy/engine/base.py", line 1910, in _execute_context
    self.dialect.do_execute(
  File "/home/airflow/.local/lib/python3.12/site-packages/sqlalchemy/engine/default.py", line 736, in do_execute
    cursor.execute(statement, parameters)
psycopg2.errors.ForeignKeyViolation: insert or update on table "task_fail" violates foreign key constraint "task_fail_ti_fkey"
DETAIL:  Key (dag_id, task_id, run_id, map_index)=(data_pipeline_etl, collect_data, scheduled__2024-11-23T00:00:00+00:00, -1) is not present in table "task_instance".


The above exception was the direct cause of the following exception:

Traceback (most recent call last):
  File "/home/airflow/.local/lib/python3.12/site-packages/airflow/task/task_runner/standard_task_runner.py", line 117, in _start_by_fork
    ret = args.func(args, dag=self.dag)
          ^^^^^^^^^^^^^^^^^^^^^^^^^^^^^
  File "/home/airflow/.local/lib/python3.12/site-packages/airflow/cli/cli_config.py", line 49, in command
    return func(*args, **kwargs)
           ^^^^^^^^^^^^^^^^^^^^^
  File "/home/airflow/.local/lib/python3.12/site-packages/airflow/utils/cli.py", line 116, in wrapper
    return f(*args, **kwargs)
           ^^^^^^^^^^^^^^^^^^
  File "/home/airflow/.local/lib/python3.12/site-packages/airflow/cli/commands/task_command.py", line 483, in task_run
    task_return_code = _run_task_by_selected_method(args, _dag, ti)
                       ^^^^^^^^^^^^^^^^^^^^^^^^^^^^^^^^^^^^^^^^^^^^
  File "/home/airflow/.local/lib/python3.12/site-packages/airflow/cli/commands/task_command.py", line 256, in _run_task_by_selected_method
    return _run_raw_task(args, ti)
           ^^^^^^^^^^^^^^^^^^^^^^^
  File "/home/airflow/.local/lib/python3.12/site-packages/airflow/cli/commands/task_command.py", line 341, in _run_raw_task
    return ti._run_raw_task(
           ^^^^^^^^^^^^^^^^^
  File "/home/airflow/.local/lib/python3.12/site-packages/airflow/utils/session.py", line 97, in wrapper
    return func(*args, session=session, **kwargs)
           ^^^^^^^^^^^^^^^^^^^^^^^^^^^^^^^^^^^^^^
  File "/home/airflow/.local/lib/python3.12/site-packages/airflow/models/taskinstance.py", line 3005, in _run_raw_task
    return _run_raw_task(
           ^^^^^^^^^^^^^^
  File "/home/airflow/.local/lib/python3.12/site-packages/airflow/models/taskinstance.py", line 327, in _run_raw_task
    ti.handle_failure(e, test_mode, context, session=session)
  File "/home/airflow/.local/lib/python3.12/site-packages/airflow/utils/session.py", line 94, in wrapper
    return func(*args, **kwargs)
           ^^^^^^^^^^^^^^^^^^^^^
  File "/home/airflow/.local/lib/python3.12/site-packages/airflow/models/taskinstance.py", line 3428, in handle_failure
    _handle_failure(
  File "/home/airflow/.local/lib/python3.12/site-packages/airflow/utils/session.py", line 94, in wrapper
    return func(*args, **kwargs)
           ^^^^^^^^^^^^^^^^^^^^^
  File "/home/airflow/.local/lib/python3.12/site-packages/airflow/api_internal/internal_api_call.py", line 166, in wrapper
    return func(*args, **kwargs)
           ^^^^^^^^^^^^^^^^^^^^^
  File "/home/airflow/.local/lib/python3.12/site-packages/airflow/models/taskinstance.py", line 1243, in _handle_failure
    TaskInstance.save_to_db(failure_context["ti"], session)
  File "/home/airflow/.local/lib/python3.12/site-packages/airflow/api_internal/internal_api_call.py", line 166, in wrapper
    return func(*args, **kwargs)
           ^^^^^^^^^^^^^^^^^^^^^
  File "/home/airflow/.local/lib/python3.12/site-packages/airflow/utils/session.py", line 94, in wrapper
    return func(*args, **kwargs)
           ^^^^^^^^^^^^^^^^^^^^^
  File "/home/airflow/.local/lib/python3.12/site-packages/airflow/models/taskinstance.py", line 3400, in save_to_db
    session.flush()
  File "/home/airflow/.local/lib/python3.12/site-packages/sqlalchemy/orm/session.py", line 3449, in flush
    self._flush(objects)
  File "/home/airflow/.local/lib/python3.12/site-packages/sqlalchemy/orm/session.py", line 3588, in _flush
    with util.safe_reraise():
         ^^^^^^^^^^^^^^^^^^^
  File "/home/airflow/.local/lib/python3.12/site-packages/sqlalchemy/util/langhelpers.py", line 70, in __exit__
    compat.raise_(
  File "/home/airflow/.local/lib/python3.12/site-packages/sqlalchemy/util/compat.py", line 211, in raise_
    raise exception
  File "/home/airflow/.local/lib/python3.12/site-packages/sqlalchemy/orm/session.py", line 3549, in _flush
    flush_context.execute()
  File "/home/airflow/.local/lib/python3.12/site-packages/sqlalchemy/orm/unitofwork.py", line 456, in execute
    rec.execute(self)
  File "/home/airflow/.local/lib/python3.12/site-packages/sqlalchemy/orm/unitofwork.py", line 630, in execute
    util.preloaded.orm_persistence.save_obj(
  File "/home/airflow/.local/lib/python3.12/site-packages/sqlalchemy/orm/persistence.py", line 245, in save_obj
    _emit_insert_statements(
  File "/home/airflow/.local/lib/python3.12/site-packages/sqlalchemy/orm/persistence.py", line 1238, in _emit_insert_statements
    result = connection._execute_20(
             ^^^^^^^^^^^^^^^^^^^^^^^
  File "/home/airflow/.local/lib/python3.12/site-packages/sqlalchemy/engine/base.py", line 1710, in _execute_20
    return meth(self, args_10style, kwargs_10style, execution_options)
           ^^^^^^^^^^^^^^^^^^^^^^^^^^^^^^^^^^^^^^^^^^^^^^^^^^^^^^^^^^^
  File "/home/airflow/.local/lib/python3.12/site-packages/sqlalchemy/sql/elements.py", line 334, in _execute_on_connection
    return connection._execute_clauseelement(
           ^^^^^^^^^^^^^^^^^^^^^^^^^^^^^^^^^^
  File "/home/airflow/.local/lib/python3.12/site-packages/sqlalchemy/engine/base.py", line 1577, in _execute_clauseelement
    ret = self._execute_context(
          ^^^^^^^^^^^^^^^^^^^^^^
  File "/home/airflow/.local/lib/python3.12/site-packages/sqlalchemy/engine/base.py", line 1953, in _execute_context
    self._handle_dbapi_exception(
  File "/home/airflow/.local/lib/python3.12/site-packages/sqlalchemy/engine/base.py", line 2134, in _handle_dbapi_exception
    util.raise_(
  File "/home/airflow/.local/lib/python3.12/site-packages/sqlalchemy/util/compat.py", line 211, in raise_
    raise exception
  File "/home/airflow/.local/lib/python3.12/site-packages/sqlalchemy/engine/base.py", line 1910, in _execute_context
    self.dialect.do_execute(
  File "/home/airflow/.local/lib/python3.12/site-packages/sqlalchemy/engine/default.py", line 736, in do_execute
    cursor.execute(statement, parameters)
sqlalchemy.exc.IntegrityError: (psycopg2.errors.ForeignKeyViolation) insert or update on table "task_fail" violates foreign key constraint "task_fail_ti_fkey"
DETAIL:  Key (dag_id, task_id, run_id, map_index)=(data_pipeline_etl, collect_data, scheduled__2024-11-23T00:00:00+00:00, -1) is not present in table "task_instance".

[SQL: INSERT INTO task_fail (task_id, dag_id, run_id, map_index, start_date, end_date, duration) VALUES (%(task_id)s, %(dag_id)s, %(run_id)s, %(map_index)s, %(start_date)s, %(end_date)s, %(duration)s) RETURNING task_fail.id]
[parameters: {'task_id': 'collect_data', 'dag_id': 'data_pipeline_etl', 'run_id': 'scheduled__2024-11-23T00:00:00+00:00', 'map_index': -1, 'start_date': datetime.datetime(2024, 11, 24, 13, 44, 19, 717411, tzinfo=Timezone('UTC')), 'end_date': datetime.datetime(2024, 11, 24, 13, 47, 11, 134062, tzinfo=Timezone('UTC')), 'duration': 171}]
(Background on this error at: https://sqlalche.me/e/14/gkpj)
[2024-11-24T13:47:11.161+0000] {process_utils.py:80} INFO - Process psutil.Process(pid=191, status='terminated', started='13:44:19') (191) terminated with exit code None
[2024-11-24T13:47:11.162+0000] {process_utils.py:80} INFO - Process psutil.Process(pid=189, status='terminated', exitcode=1, started='13:44:19') (189) terminated with exit code 1
[2024-11-24T14:13:31.589+0000] {local_task_job_runner.py:123} INFO - ::group::Pre task execution logs
[2024-11-24T14:13:31.599+0000] {taskinstance.py:2613} INFO - Dependencies all met for dep_context=non-requeueable deps ti=<TaskInstance: data_pipeline_etl.collect_data scheduled__2024-11-23T00:00:00+00:00 [queued]>
[2024-11-24T14:13:31.604+0000] {taskinstance.py:2613} INFO - Dependencies all met for dep_context=requeueable deps ti=<TaskInstance: data_pipeline_etl.collect_data scheduled__2024-11-23T00:00:00+00:00 [queued]>
[2024-11-24T14:13:31.604+0000] {taskinstance.py:2866} INFO - Starting attempt 1 of 2
[2024-11-24T14:13:31.611+0000] {taskinstance.py:2889} INFO - Executing <Task(BashOperator): collect_data> on 2024-11-23 00:00:00+00:00
[2024-11-24T14:13:31.618+0000] {logging_mixin.py:190} WARNING - /home/***/.local/lib/python3.12/site-packages/***/task/task_runner/standard_task_runner.py:70 DeprecationWarning: This process (pid=435) is multi-threaded, use of fork() may lead to deadlocks in the child.
[2024-11-24T14:13:31.618+0000] {standard_task_runner.py:72} INFO - Started process 436 to run task
[2024-11-24T14:13:31.618+0000] {standard_task_runner.py:104} INFO - Running: ['***', 'tasks', 'run', 'data_pipeline_etl', 'collect_data', 'scheduled__2024-11-23T00:00:00+00:00', '--job-id', '39', '--raw', '--subdir', 'DAGS_FOLDER/etl_pipeline_auto.py', '--cfg-path', '/tmp/tmp8aqp3ee7']
[2024-11-24T14:13:31.619+0000] {standard_task_runner.py:105} INFO - Job 39: Subtask collect_data
[2024-11-24T14:13:31.646+0000] {task_command.py:467} INFO - Running <TaskInstance: data_pipeline_etl.collect_data scheduled__2024-11-23T00:00:00+00:00 [running]> on host b15774e3675a
[2024-11-24T14:13:31.686+0000] {taskinstance.py:3132} INFO - Exporting env vars: AIRFLOW_CTX_DAG_OWNER='***' AIRFLOW_CTX_DAG_ID='data_pipeline_etl' AIRFLOW_CTX_TASK_ID='collect_data' AIRFLOW_CTX_EXECUTION_DATE='2024-11-23T00:00:00+00:00' AIRFLOW_CTX_TRY_NUMBER='1' AIRFLOW_CTX_DAG_RUN_ID='scheduled__2024-11-23T00:00:00+00:00'
[2024-11-24T14:13:31.687+0000] {taskinstance.py:731} INFO - ::endgroup::
[2024-11-24T14:13:31.700+0000] {subprocess.py:78} INFO - Tmp dir root location: /tmp
[2024-11-24T14:13:31.701+0000] {subprocess.py:88} INFO - Running command: ['/usr/bin/bash', '-c', 'python /opt/***/data-pipeline-project/product_data_scraper.py']
[2024-11-24T14:13:31.707+0000] {subprocess.py:99} INFO - Output:
[2024-11-24T14:14:03.343+0000] {subprocess.py:106} INFO - 320번 데이터 수집 시작
[2024-11-24T14:14:03.344+0000] {subprocess.py:106} INFO - 페이지 1 데이터 수집 시작 (카테고리: 320)
[2024-11-24T14:14:03.345+0000] {subprocess.py:106} INFO - 페이지 1 데이터 수집 완료 (카테고리: 320)
[2024-11-24T14:14:03.345+0000] {subprocess.py:106} INFO - 1번 페이지 추출 성공
[2024-11-24T14:14:03.345+0000] {subprocess.py:106} INFO - 페이지 2 데이터 수집 시작 (카테고리: 320)
[2024-11-24T14:14:03.346+0000] {subprocess.py:106} INFO - 페이지 2 데이터 수집 완료 (카테고리: 320)
[2024-11-24T14:14:03.346+0000] {subprocess.py:106} INFO - 2번 페이지 추출 성공
[2024-11-24T14:14:03.346+0000] {subprocess.py:106} INFO - 데이터 수집 및 저장 완료
[2024-11-24T14:14:03.346+0000] {subprocess.py:106} INFO - 310번 데이터 수집 시작
[2024-11-24T14:14:03.346+0000] {subprocess.py:106} INFO - 페이지 1 데이터 수집 시작 (카테고리: 310)
[2024-11-24T14:14:03.347+0000] {subprocess.py:106} INFO - 페이지 1 데이터 수집 완료 (카테고리: 310)
[2024-11-24T14:14:03.347+0000] {subprocess.py:106} INFO - 1번 페이지 추출 성공
[2024-11-24T14:14:03.347+0000] {subprocess.py:106} INFO - 페이지 2 데이터 수집 시작 (카테고리: 310)
[2024-11-24T14:14:03.347+0000] {subprocess.py:106} INFO - 페이지 2 데이터 수집 완료 (카테고리: 310)
[2024-11-24T14:14:03.347+0000] {subprocess.py:106} INFO - 2번 페이지 추출 성공
[2024-11-24T14:14:03.347+0000] {subprocess.py:106} INFO - 데이터 수집 및 저장 완료
[2024-11-24T14:14:03.403+0000] {subprocess.py:110} INFO - Command exited with return code 0
[2024-11-24T14:14:03.426+0000] {taskinstance.py:340} INFO - ::group::Post task execution logs
[2024-11-24T14:14:03.426+0000] {taskinstance.py:352} INFO - Marking task as SUCCESS. dag_id=data_pipeline_etl, task_id=collect_data, run_id=scheduled__2024-11-23T00:00:00+00:00, execution_date=20241123T000000, start_date=20241124T141331, end_date=20241124T141403
[2024-11-24T14:14:03.455+0000] {local_task_job_runner.py:266} INFO - Task exited with return code 0
[2024-11-24T14:14:03.472+0000] {taskinstance.py:3895} INFO - 1 downstream tasks scheduled from follow-on schedule check
[2024-11-24T14:14:03.473+0000] {local_task_job_runner.py:245} INFO - ::endgroup::
