[2024-12-21T06:42:55.942+0000] {local_task_job_runner.py:123} INFO - ::group::Pre task execution logs
[2024-12-21T06:42:55.947+0000] {taskinstance.py:2613} INFO - Dependencies all met for dep_context=non-requeueable deps ti=<TaskInstance: data_pipeline_etl.collect_data scheduled__2024-12-20T04:00:00+00:00 [queued]>
[2024-12-21T06:42:55.950+0000] {taskinstance.py:2613} INFO - Dependencies all met for dep_context=requeueable deps ti=<TaskInstance: data_pipeline_etl.collect_data scheduled__2024-12-20T04:00:00+00:00 [queued]>
[2024-12-21T06:42:55.950+0000] {taskinstance.py:2866} INFO - Starting attempt 1 of 2
[2024-12-21T06:42:55.955+0000] {taskinstance.py:2889} INFO - Executing <Task(BashOperator): collect_data> on 2024-12-20 04:00:00+00:00
[2024-12-21T06:42:55.959+0000] {logging_mixin.py:190} WARNING - /home/***/.local/lib/python3.12/site-packages/***/task/task_runner/standard_task_runner.py:70 DeprecationWarning: This process (pid=536) is multi-threaded, use of fork() may lead to deadlocks in the child.
[2024-12-21T06:42:55.959+0000] {standard_task_runner.py:72} INFO - Started process 537 to run task
[2024-12-21T06:42:55.959+0000] {standard_task_runner.py:104} INFO - Running: ['***', 'tasks', 'run', 'data_pipeline_etl', 'collect_data', 'scheduled__2024-12-20T04:00:00+00:00', '--job-id', '88', '--raw', '--subdir', 'DAGS_FOLDER/etl_pipeline_auto.py', '--cfg-path', '/tmp/tmpq5pqyzm9']
[2024-12-21T06:42:55.960+0000] {standard_task_runner.py:105} INFO - Job 88: Subtask collect_data
[2024-12-21T06:42:55.977+0000] {task_command.py:467} INFO - Running <TaskInstance: data_pipeline_etl.collect_data scheduled__2024-12-20T04:00:00+00:00 [running]> on host 9e8889dddaab
[2024-12-21T06:42:56.006+0000] {taskinstance.py:3132} INFO - Exporting env vars: AIRFLOW_CTX_DAG_OWNER='***' AIRFLOW_CTX_DAG_ID='data_pipeline_etl' AIRFLOW_CTX_TASK_ID='collect_data' AIRFLOW_CTX_EXECUTION_DATE='2024-12-20T04:00:00+00:00' AIRFLOW_CTX_TRY_NUMBER='1' AIRFLOW_CTX_DAG_RUN_ID='scheduled__2024-12-20T04:00:00+00:00'
[2024-12-21T06:42:56.006+0000] {taskinstance.py:731} INFO - ::endgroup::
[2024-12-21T06:42:56.016+0000] {subprocess.py:78} INFO - Tmp dir root location: /tmp
[2024-12-21T06:42:56.017+0000] {subprocess.py:88} INFO - Running command: ['/usr/bin/bash', '-c', 'python /opt/***/data-pipeline-project/product_data_scraper.py']
[2024-12-21T06:42:56.021+0000] {subprocess.py:99} INFO - Output:
[2024-12-21T06:44:13.275+0000] {local_task_job_runner.py:127} ERROR - Received SIGTERM. Terminating subprocesses
[2024-12-21T06:44:13.283+0000] {process_utils.py:132} INFO - Sending 15 to group 537. PIDs of all processes in the group: [539, 537]
[2024-12-21T06:44:13.284+0000] {process_utils.py:87} INFO - Sending the signal 15 to group 537
[2024-12-21T06:44:13.286+0000] {taskinstance.py:3093} ERROR - Received SIGTERM. Terminating subprocesses.
[2024-12-21T06:44:13.286+0000] {subprocess.py:117} INFO - Sending SIGTERM signal to process group
[2024-12-21T06:44:13.311+0000] {taskinstance.py:3311} ERROR - Task failed with exception
Traceback (most recent call last):
  File "/home/airflow/.local/lib/python3.12/site-packages/airflow/models/taskinstance.py", line 762, in _execute_task
    result = _execute_callable(context=context, **execute_callable_kwargs)
             ^^^^^^^^^^^^^^^^^^^^^^^^^^^^^^^^^^^^^^^^^^^^^^^^^^^^^^^^^^^^^
  File "/home/airflow/.local/lib/python3.12/site-packages/airflow/models/taskinstance.py", line 733, in _execute_callable
    return ExecutionCallableRunner(
           ^^^^^^^^^^^^^^^^^^^^^^^^
  File "/home/airflow/.local/lib/python3.12/site-packages/airflow/utils/operator_helpers.py", line 252, in run
    return self.func(*args, **kwargs)
           ^^^^^^^^^^^^^^^^^^^^^^^^^^
  File "/home/airflow/.local/lib/python3.12/site-packages/airflow/models/baseoperator.py", line 417, in wrapper
    return func(self, *args, **kwargs)
           ^^^^^^^^^^^^^^^^^^^^^^^^^^^
  File "/home/airflow/.local/lib/python3.12/site-packages/airflow/operators/bash.py", line 257, in execute
    result = self._run_inline_command(bash_path=bash_path, env=env)
             ^^^^^^^^^^^^^^^^^^^^^^^^^^^^^^^^^^^^^^^^^^^^^^^^^^^^^^
  File "/home/airflow/.local/lib/python3.12/site-packages/airflow/operators/bash.py", line 284, in _run_inline_command
    return self.subprocess_hook.run_command(
           ^^^^^^^^^^^^^^^^^^^^^^^^^^^^^^^^^
  File "/home/airflow/.local/lib/python3.12/site-packages/airflow/hooks/subprocess.py", line 104, in run_command
    for raw_line in iter(self.sub_process.stdout.readline, b""):
                    ^^^^^^^^^^^^^^^^^^^^^^^^^^^^^^^^^^^^^^^^^^^
  File "/home/airflow/.local/lib/python3.12/site-packages/airflow/models/taskinstance.py", line 3095, in signal_handler
    raise AirflowTaskTerminated("Task received SIGTERM signal")
airflow.exceptions.AirflowTaskTerminated: Task received SIGTERM signal
[2024-12-21T06:44:13.325+0000] {taskinstance.py:1225} INFO - Marking task as UP_FOR_RETRY. dag_id=data_pipeline_etl, task_id=collect_data, run_id=scheduled__2024-12-20T04:00:00+00:00, execution_date=20241220T040000, start_date=20241221T064255, end_date=20241221T064413
[2024-12-21T06:44:13.370+0000] {taskinstance.py:340} INFO - ::group::Post task execution logs
[2024-12-21T06:44:13.391+0000] {process_utils.py:80} INFO - Process psutil.Process(pid=539, status='terminated', started='06:42:55') (539) terminated with exit code None
[2024-12-21T06:44:13.391+0000] {process_utils.py:80} INFO - Process psutil.Process(pid=537, status='terminated', exitcode=2, started='06:42:55') (537) terminated with exit code 2
[2024-12-21T06:44:13.391+0000] {local_task_job_runner.py:266} INFO - Task exited with return code 143
[2024-12-21T06:44:13.403+0000] {taskinstance.py:3895} INFO - 0 downstream tasks scheduled from follow-on schedule check
