[2024-11-24T08:14:32.272+0000] {local_task_job_runner.py:123} INFO - ::group::Pre task execution logs
[2024-11-24T08:14:32.281+0000] {taskinstance.py:2613} INFO - Dependencies all met for dep_context=non-requeueable deps ti=<TaskInstance: data_pipeline_etl.collect_data manual__2024-11-24T08:08:42.863305+00:00 [queued]>
[2024-11-24T08:14:32.286+0000] {taskinstance.py:2613} INFO - Dependencies all met for dep_context=requeueable deps ti=<TaskInstance: data_pipeline_etl.collect_data manual__2024-11-24T08:08:42.863305+00:00 [queued]>
[2024-11-24T08:14:32.286+0000] {taskinstance.py:2866} INFO - Starting attempt 1 of 3
[2024-11-24T08:14:32.294+0000] {taskinstance.py:2889} INFO - Executing <Task(BashOperator): collect_data> on 2024-11-24 08:08:42.863305+00:00
[2024-11-24T08:14:32.296+0000] {standard_task_runner.py:72} INFO - Started process 76 to run task
[2024-11-24T08:14:32.298+0000] {standard_task_runner.py:104} INFO - Running: ['***', 'tasks', 'run', 'data_pipeline_etl', 'collect_data', 'manual__2024-11-24T08:08:42.863305+00:00', '--job-id', '3', '--raw', '--subdir', 'DAGS_FOLDER/etl_pipeline_auto.py', '--cfg-path', '/tmp/tmpsc1_ee5a']
[2024-11-24T08:14:32.300+0000] {standard_task_runner.py:105} INFO - Job 3: Subtask collect_data
[2024-11-24T08:14:32.325+0000] {task_command.py:467} INFO - Running <TaskInstance: data_pipeline_etl.collect_data manual__2024-11-24T08:08:42.863305+00:00 [running]> on host ab4b9bbf647e
[2024-11-24T08:14:32.363+0000] {taskinstance.py:3132} INFO - Exporting env vars: AIRFLOW_CTX_DAG_OWNER='***' AIRFLOW_CTX_DAG_ID='data_pipeline_etl' AIRFLOW_CTX_TASK_ID='collect_data' AIRFLOW_CTX_EXECUTION_DATE='2024-11-24T08:08:42.863305+00:00' AIRFLOW_CTX_TRY_NUMBER='1' AIRFLOW_CTX_DAG_RUN_ID='manual__2024-11-24T08:08:42.863305+00:00'
[2024-11-24T08:14:32.364+0000] {taskinstance.py:731} INFO - ::endgroup::
[2024-11-24T08:14:32.375+0000] {subprocess.py:78} INFO - Tmp dir root location: /tmp
[2024-11-24T08:14:32.376+0000] {subprocess.py:88} INFO - Running command: ['/usr/bin/bash', '-c', 'python /opt/***/data-pipeline-project/product_data_scraper.py']
[2024-11-24T08:14:32.381+0000] {subprocess.py:99} INFO - Output:
[2024-11-24T10:04:46.353+0000] {job.py:229} INFO - Heartbeat recovered after 6220.26 seconds
[2024-11-24T10:16:57.331+0000] {local_task_job_runner.py:127} ERROR - Received SIGTERM. Terminating subprocesses
[2024-11-24T10:16:57.337+0000] {process_utils.py:132} INFO - Sending 15 to group 76. PIDs of all processes in the group: [78, 76]
[2024-11-24T10:16:57.337+0000] {process_utils.py:87} INFO - Sending the signal 15 to group 76
[2024-11-24T10:16:57.340+0000] {taskinstance.py:3093} ERROR - Received SIGTERM. Terminating subprocesses.
[2024-11-24T10:16:57.343+0000] {subprocess.py:117} INFO - Sending SIGTERM signal to process group
[2024-11-24T10:16:57.363+0000] {taskinstance.py:3311} ERROR - Task failed with exception
Traceback (most recent call last):
  File "/home/airflow/.local/lib/python3.12/site-packages/airflow/models/taskinstance.py", line 762, in _execute_task
    result = _execute_callable(context=context, **execute_callable_kwargs)
             ^^^^^^^^^^^^^^^^^^^^^^^^^^^^^^^^^^^^^^^^^^^^^^^^^^^^^^^^^^^^^
  File "/home/airflow/.local/lib/python3.12/site-packages/airflow/models/taskinstance.py", line 733, in _execute_callable
    return ExecutionCallableRunner(
           ^^^^^^^^^^^^^^^^^^^^^^^^
  File "/home/airflow/.local/lib/python3.12/site-packages/airflow/utils/operator_helpers.py", line 252, in run
    return self.func(*args, **kwargs)
           ^^^^^^^^^^^^^^^^^^^^^^^^^^
  File "/home/airflow/.local/lib/python3.12/site-packages/airflow/models/baseoperator.py", line 417, in wrapper
    return func(self, *args, **kwargs)
           ^^^^^^^^^^^^^^^^^^^^^^^^^^^
  File "/home/airflow/.local/lib/python3.12/site-packages/airflow/operators/bash.py", line 257, in execute
    result = self._run_inline_command(bash_path=bash_path, env=env)
             ^^^^^^^^^^^^^^^^^^^^^^^^^^^^^^^^^^^^^^^^^^^^^^^^^^^^^^
  File "/home/airflow/.local/lib/python3.12/site-packages/airflow/operators/bash.py", line 284, in _run_inline_command
    return self.subprocess_hook.run_command(
           ^^^^^^^^^^^^^^^^^^^^^^^^^^^^^^^^^
  File "/home/airflow/.local/lib/python3.12/site-packages/airflow/hooks/subprocess.py", line 104, in run_command
    for raw_line in iter(self.sub_process.stdout.readline, b""):
                    ^^^^^^^^^^^^^^^^^^^^^^^^^^^^^^^^^^^^^^^^^^^
  File "/home/airflow/.local/lib/python3.12/site-packages/airflow/models/taskinstance.py", line 3095, in signal_handler
    raise AirflowTaskTerminated("Task received SIGTERM signal")
airflow.exceptions.AirflowTaskTerminated: Task received SIGTERM signal
[2024-11-24T10:16:57.373+0000] {taskinstance.py:1225} INFO - Marking task as UP_FOR_RETRY. dag_id=data_pipeline_etl, task_id=collect_data, run_id=manual__2024-11-24T08:08:42.863305+00:00, execution_date=20241124T080842, start_date=20241124T081432, end_date=20241124T101657
[2024-11-24T10:16:57.387+0000] {taskinstance.py:340} INFO - ::group::Post task execution logs
[2024-11-24T10:16:57.397+0000] {process_utils.py:80} INFO - Process psutil.Process(pid=78, status='terminated', started='08:14:31') (78) terminated with exit code None
[2024-11-24T10:16:57.398+0000] {process_utils.py:80} INFO - Process psutil.Process(pid=76, status='terminated', exitcode=2, started='08:14:31') (76) terminated with exit code 2
[2024-11-24T10:16:57.398+0000] {local_task_job_runner.py:266} INFO - Task exited with return code 143
[2024-11-24T10:16:57.420+0000] {taskinstance.py:3895} INFO - 0 downstream tasks scheduled from follow-on schedule check
[2024-11-24T10:16:58.439+0000] {local_task_job_runner.py:245} INFO - ::endgroup::
[2024-11-24T10:17:01.230+0000] {local_task_job_runner.py:123} INFO - ::group::Pre task execution logs
[2024-11-24T10:17:01.240+0000] {taskinstance.py:2603} INFO - Dependencies not met for <TaskInstance: data_pipeline_etl.collect_data manual__2024-11-24T08:08:42.863305+00:00 [up_for_retry]>, dependency 'Not In Retry Period' FAILED: Task is not ready for retry yet but will be retried automatically. Current date is 2024-11-24T10:17:01.240329+00:00 and task will be retried at 2024-11-24T10:26:57.372487+00:00.
[2024-11-24T10:17:01.241+0000] {local_task_job_runner.py:166} INFO - Task is not able to be run
