[2024-11-24T12:47:37.844+0000] {local_task_job_runner.py:123} INFO - ::group::Pre task execution logs
[2024-11-24T12:47:37.853+0000] {taskinstance.py:2613} INFO - Dependencies all met for dep_context=non-requeueable deps ti=<TaskInstance: data_pipeline_etl.collect_data manual__2024-11-24T11:22:55+00:00 [queued]>
[2024-11-24T12:47:37.858+0000] {taskinstance.py:2613} INFO - Dependencies all met for dep_context=requeueable deps ti=<TaskInstance: data_pipeline_etl.collect_data manual__2024-11-24T11:22:55+00:00 [queued]>
[2024-11-24T12:47:37.858+0000] {taskinstance.py:2866} INFO - Starting attempt 2 of 3
[2024-11-24T12:47:37.866+0000] {taskinstance.py:2889} INFO - Executing <Task(BashOperator): collect_data> on 2024-11-24 11:22:55+00:00
[2024-11-24T12:47:37.869+0000] {standard_task_runner.py:72} INFO - Started process 47 to run task
[2024-11-24T12:47:37.871+0000] {standard_task_runner.py:104} INFO - Running: ['***', 'tasks', 'run', 'data_pipeline_etl', 'collect_data', 'manual__2024-11-24T11:22:55+00:00', '--job-id', '13', '--raw', '--subdir', 'DAGS_FOLDER/etl_pipeline_auto.py', '--cfg-path', '/tmp/tmpt9o1iodd']
[2024-11-24T12:47:37.873+0000] {standard_task_runner.py:105} INFO - Job 13: Subtask collect_data
[2024-11-24T12:47:37.898+0000] {task_command.py:467} INFO - Running <TaskInstance: data_pipeline_etl.collect_data manual__2024-11-24T11:22:55+00:00 [running]> on host 5003577eea69
[2024-11-24T12:47:37.948+0000] {taskinstance.py:3132} INFO - Exporting env vars: AIRFLOW_CTX_DAG_OWNER='***' AIRFLOW_CTX_DAG_ID='data_pipeline_etl' AIRFLOW_CTX_TASK_ID='collect_data' AIRFLOW_CTX_EXECUTION_DATE='2024-11-24T11:22:55+00:00' AIRFLOW_CTX_TRY_NUMBER='2' AIRFLOW_CTX_DAG_RUN_ID='manual__2024-11-24T11:22:55+00:00'
[2024-11-24T12:47:37.948+0000] {taskinstance.py:731} INFO - ::endgroup::
[2024-11-24T12:47:37.978+0000] {subprocess.py:78} INFO - Tmp dir root location: /tmp
[2024-11-24T12:47:37.978+0000] {subprocess.py:88} INFO - Running command: ['/usr/bin/bash', '-c', '/home/***/.local/bin/python /opt/***/data-pipeline-project/product_data_scraper.py']
[2024-11-24T12:47:37.983+0000] {subprocess.py:99} INFO - Output:
[2024-11-24T12:47:39.584+0000] {subprocess.py:106} INFO - Exception in thread Thread-2 (collect_all):
[2024-11-24T12:47:39.585+0000] {subprocess.py:106} INFO - Traceback (most recent call last):
[2024-11-24T12:47:39.585+0000] {subprocess.py:106} INFO -   File "/home/***/.local/lib/python3.12/site-packages/urllib3/connection.py", line 199, in _new_conn
[2024-11-24T12:47:39.586+0000] {subprocess.py:106} INFO - Exception in thread Thread-1 (collect_all):
[2024-11-24T12:47:39.586+0000] {subprocess.py:106} INFO - Traceback (most recent call last):
[2024-11-24T12:47:39.586+0000] {subprocess.py:106} INFO -   File "/home/***/.local/lib/python3.12/site-packages/urllib3/connection.py", line 199, in _new_conn
[2024-11-24T12:47:39.586+0000] {subprocess.py:106} INFO -     sock = connection.create_connection(
[2024-11-24T12:47:39.587+0000] {subprocess.py:106} INFO -            ^^^^^^^^^^^^^^^^^^^^^^^^^^^^^
[2024-11-24T12:47:39.587+0000] {subprocess.py:106} INFO -   File "/home/***/.local/lib/python3.12/site-packages/urllib3/util/connection.py", line 60, in create_connection
[2024-11-24T12:47:39.587+0000] {subprocess.py:106} INFO -     sock = connection.create_connection(
[2024-11-24T12:47:39.588+0000] {subprocess.py:106} INFO -            ^^^^^^^^^^^^^^^^^^^^^^^^^^^^^
[2024-11-24T12:47:39.588+0000] {subprocess.py:106} INFO -   File "/home/***/.local/lib/python3.12/site-packages/urllib3/util/connection.py", line 60, in create_connection
[2024-11-24T12:47:39.589+0000] {subprocess.py:106} INFO -     for res in socket.getaddrinfo(host, port, family, socket.SOCK_STREAM):
[2024-11-24T12:47:39.591+0000] {subprocess.py:106} INFO -                ^^^^^^^^^^^^^^^^^^^^^^^^^^^^^^^^^^^^^^^^^^^^^^^^^^^^^^^^^^
[2024-11-24T12:47:39.591+0000] {subprocess.py:106} INFO -   File "/usr/local/lib/python3.12/socket.py", line 976, in getaddrinfo
[2024-11-24T12:47:39.591+0000] {subprocess.py:106} INFO -     for res in socket.getaddrinfo(host, port, family, socket.SOCK_STREAM):
[2024-11-24T12:47:39.592+0000] {subprocess.py:106} INFO -                ^^^^^^^^^^^^^^^^^^^^^^^^^^^^^^^^^^^^^^^^^^^^^^^^^^^^^^^^^^
[2024-11-24T12:47:39.592+0000] {subprocess.py:106} INFO -   File "/usr/local/lib/python3.12/socket.py", line 976, in getaddrinfo
[2024-11-24T12:47:39.593+0000] {subprocess.py:106} INFO -     for res in _socket.getaddrinfo(host, port, family, type, proto, flags):
[2024-11-24T12:47:39.594+0000] {subprocess.py:106} INFO -                ^^^^^^^^^^^^^^^^^^^^^^^^^^^^^^^^^^^^^^^^^^^^^^^^^^^^^^^^^^^
[2024-11-24T12:47:39.594+0000] {subprocess.py:106} INFO - socket.gaierror: [Errno -2] Name or service not known
[2024-11-24T12:47:39.594+0000] {subprocess.py:106} INFO - 
[2024-11-24T12:47:39.595+0000] {subprocess.py:106} INFO - The above exception was the direct cause of the following exception:
[2024-11-24T12:47:39.595+0000] {subprocess.py:106} INFO - 
[2024-11-24T12:47:39.596+0000] {subprocess.py:106} INFO - Traceback (most recent call last):
[2024-11-24T12:47:39.596+0000] {subprocess.py:106} INFO -   File "/home/***/.local/lib/python3.12/site-packages/urllib3/connectionpool.py", line 789, in urlopen
[2024-11-24T12:47:39.597+0000] {subprocess.py:106} INFO -     for res in _socket.getaddrinfo(host, port, family, type, proto, flags):
[2024-11-24T12:47:39.597+0000] {subprocess.py:106} INFO -                ^^^^^^^^^^^^^^^^^^^^^^^^^^^^^^^^^^^^^^^^^^^^^^^^^^^^^^^^^^^
[2024-11-24T12:47:39.597+0000] {subprocess.py:106} INFO - socket.gaierror: [Errno -2] Name or service not known
[2024-11-24T12:47:39.598+0000] {subprocess.py:106} INFO - 
[2024-11-24T12:47:39.598+0000] {subprocess.py:106} INFO - The above exception was the direct cause of the following exception:
[2024-11-24T12:47:39.598+0000] {subprocess.py:106} INFO - 
[2024-11-24T12:47:39.598+0000] {subprocess.py:106} INFO - Traceback (most recent call last):
[2024-11-24T12:47:39.598+0000] {subprocess.py:106} INFO -   File "/home/***/.local/lib/python3.12/site-packages/urllib3/connectionpool.py", line 789, in urlopen
[2024-11-24T12:47:39.598+0000] {subprocess.py:106} INFO -     response = self._make_request(
[2024-11-24T12:47:39.598+0000] {subprocess.py:106} INFO -                ^^^^^^^^^^^^^^^^^^^
[2024-11-24T12:47:39.599+0000] {subprocess.py:106} INFO -   File "/home/***/.local/lib/python3.12/site-packages/urllib3/connectionpool.py", line 495, in _make_request
[2024-11-24T12:47:39.599+0000] {subprocess.py:106} INFO -     conn.request(
[2024-11-24T12:47:39.599+0000] {subprocess.py:106} INFO -   File "/home/***/.local/lib/python3.12/site-packages/urllib3/connection.py", line 441, in request
[2024-11-24T12:47:39.599+0000] {subprocess.py:106} INFO -     self.endheaders()
[2024-11-24T12:47:39.599+0000] {subprocess.py:106} INFO -   File "/usr/local/lib/python3.12/http/client.py", line 1331, in endheaders
[2024-11-24T12:47:39.599+0000] {subprocess.py:106} INFO -     self._send_output(message_body, encode_chunked=encode_chunked)
[2024-11-24T12:47:39.599+0000] {subprocess.py:106} INFO -   File "/usr/local/lib/python3.12/http/client.py", line 1091, in _send_output
[2024-11-24T12:47:39.600+0000] {subprocess.py:106} INFO -     self.send(msg)
[2024-11-24T12:47:39.600+0000] {subprocess.py:106} INFO -   File "/usr/local/lib/python3.12/http/client.py", line 1035, in send
[2024-11-24T12:47:39.600+0000] {subprocess.py:106} INFO -     response = self._make_request(
[2024-11-24T12:47:39.600+0000] {subprocess.py:106} INFO -                ^^^^^^^^^^^^^^^^^^^
[2024-11-24T12:47:39.600+0000] {subprocess.py:106} INFO -   File "/home/***/.local/lib/python3.12/site-packages/urllib3/connectionpool.py", line 495, in _make_request
[2024-11-24T12:47:39.600+0000] {subprocess.py:106} INFO -     self.connect()
[2024-11-24T12:47:39.600+0000] {subprocess.py:106} INFO -   File "/home/***/.local/lib/python3.12/site-packages/urllib3/connection.py", line 279, in connect
[2024-11-24T12:47:39.600+0000] {subprocess.py:106} INFO -     conn.request(
[2024-11-24T12:47:39.600+0000] {subprocess.py:106} INFO -   File "/home/***/.local/lib/python3.12/site-packages/urllib3/connection.py", line 441, in request
[2024-11-24T12:47:39.600+0000] {subprocess.py:106} INFO -     self.sock = self._new_conn()
[2024-11-24T12:47:39.600+0000] {subprocess.py:106} INFO -                 ^^^^^^^^^^^^^^^^
[2024-11-24T12:47:39.601+0000] {subprocess.py:106} INFO -   File "/home/***/.local/lib/python3.12/site-packages/urllib3/connection.py", line 206, in _new_conn
[2024-11-24T12:47:39.601+0000] {subprocess.py:106} INFO -     raise NameResolutionError(self.host, self, e) from e
[2024-11-24T12:47:39.601+0000] {subprocess.py:106} INFO - urllib3.exceptions.NameResolutionError: <urllib3.connection.HTTPConnection object at 0xffff99fa4170>: Failed to resolve 'selenium' ([Errno -2] Name or service not known)
[2024-11-24T12:47:39.601+0000] {subprocess.py:106} INFO - 
[2024-11-24T12:47:39.601+0000] {subprocess.py:106} INFO - The above exception was the direct cause of the following exception:
[2024-11-24T12:47:39.601+0000] {subprocess.py:106} INFO - 
[2024-11-24T12:47:39.601+0000] {subprocess.py:106} INFO - Traceback (most recent call last):
[2024-11-24T12:47:39.601+0000] {subprocess.py:106} INFO -   File "/usr/local/lib/python3.12/threading.py", line 1075, in _bootstrap_inner
[2024-11-24T12:47:39.601+0000] {subprocess.py:106} INFO -     self.endheaders()
[2024-11-24T12:47:39.601+0000] {subprocess.py:106} INFO -   File "/usr/local/lib/python3.12/http/client.py", line 1331, in endheaders
[2024-11-24T12:47:39.601+0000] {subprocess.py:106} INFO -     self.run()
[2024-11-24T12:47:39.602+0000] {subprocess.py:106} INFO -   File "/usr/local/lib/python3.12/threading.py", line 1012, in run
[2024-11-24T12:47:39.602+0000] {subprocess.py:106} INFO -     self._target(*self._args, **self._kwargs)
[2024-11-24T12:47:39.602+0000] {subprocess.py:106} INFO -   File "/opt/***/data-pipeline-project/product_data_scraper.py", line 72, in collect_all
[2024-11-24T12:47:39.602+0000] {subprocess.py:106} INFO -     self._send_output(message_body, encode_chunked=encode_chunked)
[2024-11-24T12:47:39.602+0000] {subprocess.py:106} INFO -   File "/usr/local/lib/python3.12/http/client.py", line 1091, in _send_output
[2024-11-24T12:47:39.602+0000] {subprocess.py:106} INFO -     self.send(msg)
[2024-11-24T12:47:39.602+0000] {subprocess.py:106} INFO -   File "/usr/local/lib/python3.12/http/client.py", line 1035, in send
[2024-11-24T12:47:39.602+0000] {subprocess.py:106} INFO -     self.connect()
[2024-11-24T12:47:39.602+0000] {subprocess.py:106} INFO -   File "/home/***/.local/lib/python3.12/site-packages/urllib3/connection.py", line 279, in connect
[2024-11-24T12:47:39.602+0000] {subprocess.py:106} INFO -     self.sock = self._new_conn()
[2024-11-24T12:47:39.602+0000] {subprocess.py:106} INFO -                 ^^^^^^^^^^^^^^^^
[2024-11-24T12:47:39.603+0000] {subprocess.py:106} INFO -   File "/home/***/.local/lib/python3.12/site-packages/urllib3/connection.py", line 206, in _new_conn
[2024-11-24T12:47:39.603+0000] {subprocess.py:106} INFO -     raise NameResolutionError(self.host, self, e) from e
[2024-11-24T12:47:39.603+0000] {subprocess.py:106} INFO - urllib3.exceptions.NameResolutionError: <urllib3.connection.HTTPConnection object at 0xffff99fa4410>: Failed to resolve 'selenium' ([Errno -2] Name or service not known)
[2024-11-24T12:47:39.603+0000] {subprocess.py:106} INFO - 
[2024-11-24T12:47:39.603+0000] {subprocess.py:106} INFO - The above exception was the direct cause of the following exception:
[2024-11-24T12:47:39.603+0000] {subprocess.py:106} INFO - 
[2024-11-24T12:47:39.603+0000] {subprocess.py:106} INFO - Traceback (most recent call last):
[2024-11-24T12:47:39.603+0000] {subprocess.py:106} INFO -   File "/usr/local/lib/python3.12/threading.py", line 1075, in _bootstrap_inner
[2024-11-24T12:47:39.603+0000] {subprocess.py:106} INFO -     self.run()
[2024-11-24T12:47:39.603+0000] {subprocess.py:106} INFO -   File "/usr/local/lib/python3.12/threading.py", line 1012, in run
[2024-11-24T12:47:39.603+0000] {subprocess.py:106} INFO -     self._target(*self._args, **self._kwargs)
[2024-11-24T12:47:39.603+0000] {subprocess.py:106} INFO -   File "/opt/***/data-pipeline-project/product_data_scraper.py", line 72, in collect_all
[2024-11-24T12:47:39.604+0000] {subprocess.py:106} INFO -     driver = webdriver.Remote(
[2024-11-24T12:47:39.604+0000] {subprocess.py:106} INFO -              ^^^^^^^^^^^^^^^^^
[2024-11-24T12:47:39.604+0000] {subprocess.py:106} INFO -   File "/home/***/.local/lib/python3.12/site-packages/selenium/webdriver/remote/webdriver.py", line 238, in __init__
[2024-11-24T12:47:39.604+0000] {subprocess.py:106} INFO -     self.start_session(capabilities)
[2024-11-24T12:47:39.604+0000] {subprocess.py:106} INFO -   File "/home/***/.local/lib/python3.12/site-packages/selenium/webdriver/remote/webdriver.py", line 325, in start_session
[2024-11-24T12:47:39.604+0000] {subprocess.py:106} INFO -     response = self.execute(Command.NEW_SESSION, caps)["value"]
[2024-11-24T12:47:39.604+0000] {subprocess.py:106} INFO -                ^^^^^^^^^^^^^^^^^^^^^^^^^^^^^^^^^^^^^^^
[2024-11-24T12:47:39.605+0000] {subprocess.py:106} INFO -   File "/home/***/.local/lib/python3.12/site-packages/selenium/webdriver/remote/webdriver.py", line 378, in execute
[2024-11-24T12:47:39.605+0000] {subprocess.py:106} INFO -     response = self.command_executor.execute(driver_command, params)
[2024-11-24T12:47:39.605+0000] {subprocess.py:106} INFO -                ^^^^^^^^^^^^^^^^^^^^^^^^^^^^^^^^^^^^^^^^^^^^^^^^^^^^^
[2024-11-24T12:47:39.605+0000] {subprocess.py:106} INFO -   File "/home/***/.local/lib/python3.12/site-packages/selenium/webdriver/remote/remote_connection.py", line 391, in execute
[2024-11-24T12:47:39.605+0000] {subprocess.py:106} INFO -     driver = webdriver.Remote(
[2024-11-24T12:47:39.605+0000] {subprocess.py:106} INFO -              ^^^^^^^^^^^^^^^^^
[2024-11-24T12:47:39.605+0000] {subprocess.py:106} INFO -   File "/home/***/.local/lib/python3.12/site-packages/selenium/webdriver/remote/webdriver.py", line 238, in __init__
[2024-11-24T12:47:39.605+0000] {subprocess.py:106} INFO -     self.start_session(capabilities)
[2024-11-24T12:47:39.606+0000] {subprocess.py:106} INFO -   File "/home/***/.local/lib/python3.12/site-packages/selenium/webdriver/remote/webdriver.py", line 325, in start_session
[2024-11-24T12:47:39.606+0000] {subprocess.py:106} INFO -     response = self.execute(Command.NEW_SESSION, caps)["value"]
[2024-11-24T12:47:39.606+0000] {subprocess.py:106} INFO -                ^^^^^^^^^^^^^^^^^^^^^^^^^^^^^^^^^^^^^^^
[2024-11-24T12:47:39.606+0000] {subprocess.py:106} INFO -   File "/home/***/.local/lib/python3.12/site-packages/selenium/webdriver/remote/webdriver.py", line 378, in execute
[2024-11-24T12:47:39.606+0000] {subprocess.py:106} INFO -     response = self.command_executor.execute(driver_command, params)
[2024-11-24T12:47:39.606+0000] {subprocess.py:106} INFO -                ^^^^^^^^^^^^^^^^^^^^^^^^^^^^^^^^^^^^^^^^^^^^^^^^^^^^^
[2024-11-24T12:47:39.606+0000] {subprocess.py:106} INFO -   File "/home/***/.local/lib/python3.12/site-packages/selenium/webdriver/remote/remote_connection.py", line 391, in execute
[2024-11-24T12:47:39.606+0000] {subprocess.py:106} INFO -     return self._request(command_info[0], url, body=data)
[2024-11-24T12:47:39.607+0000] {subprocess.py:106} INFO -            ^^^^^^^^^^^^^^^^^^^^^^^^^^^^^^^^^^^^^^^^^^^^^^
[2024-11-24T12:47:39.607+0000] {subprocess.py:106} INFO -   File "/home/***/.local/lib/python3.12/site-packages/selenium/webdriver/remote/remote_connection.py", line 415, in _request
[2024-11-24T12:47:39.607+0000] {subprocess.py:106} INFO -     response = self._conn.request(method, url, body=body, headers=headers, timeout=self._client_config.timeout)
[2024-11-24T12:47:39.607+0000] {subprocess.py:106} INFO -                ^^^^^^^^^^^^^^^^^^^^^^^^^^^^^^^^^^^^^^^^^^^^^^^^^^^^^^^^^^^^^^^^^^^^^^^^^^^^^^^^^^^^^^^^^^^^^^^^
[2024-11-24T12:47:39.607+0000] {subprocess.py:106} INFO -   File "/home/***/.local/lib/python3.12/site-packages/urllib3/_request_methods.py", line 143, in request
[2024-11-24T12:47:39.607+0000] {subprocess.py:106} INFO -     return self._request(command_info[0], url, body=data)
[2024-11-24T12:47:39.607+0000] {subprocess.py:106} INFO -            ^^^^^^^^^^^^^^^^^^^^^^^^^^^^^^^^^^^^^^^^^^^^^^
[2024-11-24T12:47:39.608+0000] {subprocess.py:106} INFO -   File "/home/***/.local/lib/python3.12/site-packages/selenium/webdriver/remote/remote_connection.py", line 415, in _request
[2024-11-24T12:47:39.608+0000] {subprocess.py:106} INFO -     response = self._conn.request(method, url, body=body, headers=headers, timeout=self._client_config.timeout)
[2024-11-24T12:47:39.608+0000] {subprocess.py:106} INFO -                ^^^^^^^^^^^^^^^^^^^^^^^^^^^^^^^^^^^^^^^^^^^^^^^^^^^^^^^^^^^^^^^^^^^^^^^^^^^^^^^^^^^^^^^^^^^^^^^^
[2024-11-24T12:47:39.608+0000] {subprocess.py:106} INFO -   File "/home/***/.local/lib/python3.12/site-packages/urllib3/_request_methods.py", line 143, in request
[2024-11-24T12:47:39.608+0000] {subprocess.py:106} INFO -     return self.request_encode_body(
[2024-11-24T12:47:39.608+0000] {subprocess.py:106} INFO -            ^^^^^^^^^^^^^^^^^^^^^^^^^
[2024-11-24T12:47:39.608+0000] {subprocess.py:106} INFO -   File "/home/***/.local/lib/python3.12/site-packages/urllib3/_request_methods.py", line 278, in request_encode_body
[2024-11-24T12:47:39.609+0000] {subprocess.py:106} INFO -     return self.urlopen(method, url, **extra_kw)
[2024-11-24T12:47:39.609+0000] {subprocess.py:106} INFO -            ^^^^^^^^^^^^^^^^^^^^^^^^^^^^^^^^^^^^^
[2024-11-24T12:47:39.609+0000] {subprocess.py:106} INFO -   File "/home/***/.local/lib/python3.12/site-packages/urllib3/poolmanager.py", line 443, in urlopen
[2024-11-24T12:47:39.609+0000] {subprocess.py:106} INFO -     return self.request_encode_body(
[2024-11-24T12:47:39.609+0000] {subprocess.py:106} INFO -            ^^^^^^^^^^^^^^^^^^^^^^^^^
[2024-11-24T12:47:39.609+0000] {subprocess.py:106} INFO -   File "/home/***/.local/lib/python3.12/site-packages/urllib3/_request_methods.py", line 278, in request_encode_body
[2024-11-24T12:47:39.609+0000] {subprocess.py:106} INFO -     response = conn.urlopen(method, u.request_uri, **kw)
[2024-11-24T12:47:39.610+0000] {subprocess.py:106} INFO -                ^^^^^^^^^^^^^^^^^^^^^^^^^^^^^^^^^^^^^^^^^
[2024-11-24T12:47:39.610+0000] {subprocess.py:106} INFO -   File "/home/***/.local/lib/python3.12/site-packages/urllib3/connectionpool.py", line 873, in urlopen
[2024-11-24T12:47:39.610+0000] {subprocess.py:106} INFO -     return self.urlopen(method, url, **extra_kw)
[2024-11-24T12:47:39.610+0000] {subprocess.py:106} INFO -            ^^^^^^^^^^^^^^^^^^^^^^^^^^^^^^^^^^^^^
[2024-11-24T12:47:39.610+0000] {subprocess.py:106} INFO -   File "/home/***/.local/lib/python3.12/site-packages/urllib3/poolmanager.py", line 443, in urlopen
[2024-11-24T12:47:39.610+0000] {subprocess.py:106} INFO -     response = conn.urlopen(method, u.request_uri, **kw)
[2024-11-24T12:47:39.610+0000] {subprocess.py:106} INFO -                ^^^^^^^^^^^^^^^^^^^^^^^^^^^^^^^^^^^^^^^^^
[2024-11-24T12:47:39.611+0000] {subprocess.py:106} INFO -   File "/home/***/.local/lib/python3.12/site-packages/urllib3/connectionpool.py", line 873, in urlopen
[2024-11-24T12:47:39.611+0000] {subprocess.py:106} INFO -     return self.urlopen(
[2024-11-24T12:47:39.611+0000] {subprocess.py:106} INFO -            ^^^^^^^^^^^^^
[2024-11-24T12:47:39.611+0000] {subprocess.py:106} INFO -   File "/home/***/.local/lib/python3.12/site-packages/urllib3/connectionpool.py", line 873, in urlopen
[2024-11-24T12:47:39.611+0000] {subprocess.py:106} INFO -     return self.urlopen(
[2024-11-24T12:47:39.611+0000] {subprocess.py:106} INFO -            ^^^^^^^^^^^^^
[2024-11-24T12:47:39.612+0000] {subprocess.py:106} INFO -   File "/home/***/.local/lib/python3.12/site-packages/urllib3/connectionpool.py", line 873, in urlopen
[2024-11-24T12:47:39.612+0000] {subprocess.py:106} INFO -     return self.urlopen(
[2024-11-24T12:47:39.612+0000] {subprocess.py:106} INFO -            ^^^^^^^^^^^^^
[2024-11-24T12:47:39.612+0000] {subprocess.py:106} INFO -   File "/home/***/.local/lib/python3.12/site-packages/urllib3/connectionpool.py", line 873, in urlopen
[2024-11-24T12:47:39.612+0000] {subprocess.py:106} INFO -     return self.urlopen(
[2024-11-24T12:47:39.612+0000] {subprocess.py:106} INFO -            ^^^^^^^^^^^^^
[2024-11-24T12:47:39.612+0000] {subprocess.py:106} INFO -   File "/home/***/.local/lib/python3.12/site-packages/urllib3/connectionpool.py", line 843, in urlopen
[2024-11-24T12:47:39.613+0000] {subprocess.py:106} INFO -     return self.urlopen(
[2024-11-24T12:47:39.613+0000] {subprocess.py:106} INFO -     retries = retries.increment(
[2024-11-24T12:47:39.613+0000] {subprocess.py:106} INFO -            ^^^^^^^^^^^^^
[2024-11-24T12:47:39.613+0000] {subprocess.py:106} INFO -   File "/home/***/.local/lib/python3.12/site-packages/urllib3/connectionpool.py", line 873, in urlopen
[2024-11-24T12:47:39.613+0000] {subprocess.py:106} INFO -               ^^^^^^^^^^^^^^^^^^
[2024-11-24T12:47:39.613+0000] {subprocess.py:106} INFO -   File "/home/***/.local/lib/python3.12/site-packages/urllib3/util/retry.py", line 519, in increment
[2024-11-24T12:47:39.613+0000] {subprocess.py:106} INFO -     return self.urlopen(
[2024-11-24T12:47:39.614+0000] {subprocess.py:106} INFO -            ^^^^^^^^^^^^^
[2024-11-24T12:47:39.614+0000] {subprocess.py:106} INFO -   File "/home/***/.local/lib/python3.12/site-packages/urllib3/connectionpool.py", line 843, in urlopen
[2024-11-24T12:47:39.614+0000] {subprocess.py:106} INFO -     raise MaxRetryError(_pool, url, reason) from reason  # type: ignore[arg-type]
[2024-11-24T12:47:39.614+0000] {subprocess.py:106} INFO -     ^^^^^^^^^^^^^^^^^^^^^^^^^^^^^^^^^^^^^^^^^^^^^^^^^^^
[2024-11-24T12:47:39.615+0000] {subprocess.py:106} INFO - urllib3.exceptions.MaxRetryError: HTTPConnectionPool(host='selenium', port=4444): Max retries exceeded with url: /wd/hub/session (Caused by NameResolutionError("<urllib3.connection.HTTPConnection object at 0xffff99fa4170>: Failed to resolve 'selenium' ([Errno -2] Name or service not known)"))
[2024-11-24T12:47:39.615+0000] {subprocess.py:106} INFO -     retries = retries.increment(
[2024-11-24T12:47:39.615+0000] {subprocess.py:106} INFO -               ^^^^^^^^^^^^^^^^^^
[2024-11-24T12:47:39.615+0000] {subprocess.py:106} INFO -   File "/home/***/.local/lib/python3.12/site-packages/urllib3/util/retry.py", line 519, in increment
[2024-11-24T12:47:39.615+0000] {subprocess.py:106} INFO -     raise MaxRetryError(_pool, url, reason) from reason  # type: ignore[arg-type]
[2024-11-24T12:47:39.615+0000] {subprocess.py:106} INFO -     ^^^^^^^^^^^^^^^^^^^^^^^^^^^^^^^^^^^^^^^^^^^^^^^^^^^
[2024-11-24T12:47:39.615+0000] {subprocess.py:106} INFO - urllib3.exceptions.MaxRetryError: HTTPConnectionPool(host='selenium', port=4444): Max retries exceeded with url: /wd/hub/session (Caused by NameResolutionError("<urllib3.connection.HTTPConnection object at 0xffff99fa4410>: Failed to resolve 'selenium' ([Errno -2] Name or service not known)"))
[2024-11-24T12:49:06.343+0000] {local_task_job_runner.py:127} ERROR - Received SIGTERM. Terminating subprocesses
[2024-11-24T12:49:06.347+0000] {process_utils.py:132} INFO - Sending 15 to group 47. PIDs of all processes in the group: [49, 47]
[2024-11-24T12:49:06.347+0000] {process_utils.py:87} INFO - Sending the signal 15 to group 47
[2024-11-24T12:49:06.348+0000] {taskinstance.py:3093} ERROR - Received SIGTERM. Terminating subprocesses.
[2024-11-24T12:49:06.349+0000] {subprocess.py:117} INFO - Sending SIGTERM signal to process group
[2024-11-24T12:49:06.358+0000] {taskinstance.py:3311} ERROR - Task failed with exception
Traceback (most recent call last):
  File "/home/airflow/.local/lib/python3.12/site-packages/airflow/models/taskinstance.py", line 762, in _execute_task
    result = _execute_callable(context=context, **execute_callable_kwargs)
             ^^^^^^^^^^^^^^^^^^^^^^^^^^^^^^^^^^^^^^^^^^^^^^^^^^^^^^^^^^^^^
  File "/home/airflow/.local/lib/python3.12/site-packages/airflow/models/taskinstance.py", line 733, in _execute_callable
    return ExecutionCallableRunner(
           ^^^^^^^^^^^^^^^^^^^^^^^^
  File "/home/airflow/.local/lib/python3.12/site-packages/airflow/utils/operator_helpers.py", line 252, in run
    return self.func(*args, **kwargs)
           ^^^^^^^^^^^^^^^^^^^^^^^^^^
  File "/home/airflow/.local/lib/python3.12/site-packages/airflow/models/baseoperator.py", line 417, in wrapper
    return func(self, *args, **kwargs)
           ^^^^^^^^^^^^^^^^^^^^^^^^^^^
  File "/home/airflow/.local/lib/python3.12/site-packages/airflow/operators/bash.py", line 257, in execute
    result = self._run_inline_command(bash_path=bash_path, env=env)
             ^^^^^^^^^^^^^^^^^^^^^^^^^^^^^^^^^^^^^^^^^^^^^^^^^^^^^^
  File "/home/airflow/.local/lib/python3.12/site-packages/airflow/operators/bash.py", line 284, in _run_inline_command
    return self.subprocess_hook.run_command(
           ^^^^^^^^^^^^^^^^^^^^^^^^^^^^^^^^^
  File "/home/airflow/.local/lib/python3.12/site-packages/airflow/hooks/subprocess.py", line 104, in run_command
    for raw_line in iter(self.sub_process.stdout.readline, b""):
                    ^^^^^^^^^^^^^^^^^^^^^^^^^^^^^^^^^^^^^^^^^^^
  File "/home/airflow/.local/lib/python3.12/site-packages/airflow/models/taskinstance.py", line 3095, in signal_handler
    raise AirflowTaskTerminated("Task received SIGTERM signal")
airflow.exceptions.AirflowTaskTerminated: Task received SIGTERM signal
[2024-11-24T12:49:06.365+0000] {taskinstance.py:1225} INFO - Marking task as UP_FOR_RETRY. dag_id=data_pipeline_etl, task_id=collect_data, run_id=manual__2024-11-24T11:22:55+00:00, execution_date=20241124T112255, start_date=20241124T124737, end_date=20241124T124906
[2024-11-24T12:49:06.375+0000] {taskinstance.py:340} INFO - ::group::Post task execution logs
[2024-11-24T12:49:06.381+0000] {process_utils.py:80} INFO - Process psutil.Process(pid=49, status='terminated', started='12:47:37') (49) terminated with exit code None
[2024-11-24T12:49:06.382+0000] {process_utils.py:80} INFO - Process psutil.Process(pid=47, status='terminated', exitcode=2, started='12:47:37') (47) terminated with exit code 2
[2024-11-24T12:49:06.382+0000] {local_task_job_runner.py:266} INFO - Task exited with return code 143
[2024-11-24T12:49:06.397+0000] {taskinstance.py:3895} INFO - 0 downstream tasks scheduled from follow-on schedule check
[2024-11-24T12:49:09.599+0000] {local_task_job_runner.py:123} INFO - ::group::Pre task execution logs
[2024-11-24T12:49:09.605+0000] {taskinstance.py:2603} INFO - Dependencies not met for <TaskInstance: data_pipeline_etl.collect_data manual__2024-11-24T11:22:55+00:00 [up_for_retry]>, dependency 'Not In Retry Period' FAILED: Task is not ready for retry yet but will be retried automatically. Current date is 2024-11-24T12:49:09.605433+00:00 and task will be retried at 2024-11-24T12:54:06.364959+00:00.
[2024-11-24T12:49:09.609+0000] {local_task_job_runner.py:166} INFO - Task is not able to be run
