[2024-11-22T09:35:03.126+0000] {local_task_job_runner.py:123} INFO - ::group::Pre task execution logs
[2024-11-22T09:35:03.139+0000] {taskinstance.py:2613} INFO - Dependencies all met for dep_context=non-requeueable deps ti=<TaskInstance: data_pipeline_etl.collect_data scheduled__2024-11-22T00:00:00+00:00 [queued]>
[2024-11-22T09:35:03.147+0000] {taskinstance.py:2613} INFO - Dependencies all met for dep_context=requeueable deps ti=<TaskInstance: data_pipeline_etl.collect_data scheduled__2024-11-22T00:00:00+00:00 [queued]>
[2024-11-22T09:35:03.148+0000] {taskinstance.py:2866} INFO - Starting attempt 1 of 2
[2024-11-22T09:35:03.157+0000] {taskinstance.py:2889} INFO - Executing <Task(BashOperator): collect_data> on 2024-11-22 00:00:00+00:00
[2024-11-22T09:35:03.159+0000] {standard_task_runner.py:72} INFO - Started process 45 to run task
[2024-11-22T09:35:03.162+0000] {standard_task_runner.py:104} INFO - Running: ['***', 'tasks', 'run', 'data_pipeline_etl', 'collect_data', 'scheduled__2024-11-22T00:00:00+00:00', '--job-id', '4', '--raw', '--subdir', 'DAGS_FOLDER/etl_pipeline_auto.py', '--cfg-path', '/tmp/tmpw4mng7qf']
[2024-11-22T09:35:03.164+0000] {standard_task_runner.py:105} INFO - Job 4: Subtask collect_data
[2024-11-22T09:35:03.213+0000] {task_command.py:467} INFO - Running <TaskInstance: data_pipeline_etl.collect_data scheduled__2024-11-22T00:00:00+00:00 [running]> on host 8193587f3ea8
[2024-11-22T09:35:03.269+0000] {taskinstance.py:3132} INFO - Exporting env vars: AIRFLOW_CTX_DAG_OWNER='***' AIRFLOW_CTX_DAG_ID='data_pipeline_etl' AIRFLOW_CTX_TASK_ID='collect_data' AIRFLOW_CTX_EXECUTION_DATE='2024-11-22T00:00:00+00:00' AIRFLOW_CTX_TRY_NUMBER='1' AIRFLOW_CTX_DAG_RUN_ID='scheduled__2024-11-22T00:00:00+00:00'
[2024-11-22T09:35:03.270+0000] {taskinstance.py:731} INFO - ::endgroup::
[2024-11-22T09:35:03.306+0000] {subprocess.py:78} INFO - Tmp dir root location: /tmp
[2024-11-22T09:35:03.309+0000] {subprocess.py:88} INFO - Running command: ['/usr/bin/bash', '-c', 'python /opt/***/data-pipeline-project/product_data_scraper.py']
[2024-11-22T09:35:03.313+0000] {subprocess.py:99} INFO - Output:
[2024-11-22T10:09:50.966+0000] {local_task_job_runner.py:127} ERROR - Received SIGTERM. Terminating subprocesses
[2024-11-22T10:09:50.975+0000] {process_utils.py:132} INFO - Sending 15 to group 45. PIDs of all processes in the group: [47, 45]
[2024-11-22T10:09:50.975+0000] {process_utils.py:87} INFO - Sending the signal 15 to group 45
[2024-11-22T10:09:50.977+0000] {taskinstance.py:3093} ERROR - Received SIGTERM. Terminating subprocesses.
[2024-11-22T10:09:50.980+0000] {subprocess.py:117} INFO - Sending SIGTERM signal to process group
[2024-11-22T10:09:51.008+0000] {taskinstance.py:3311} ERROR - Task failed with exception
Traceback (most recent call last):
  File "/home/airflow/.local/lib/python3.12/site-packages/airflow/models/taskinstance.py", line 767, in _execute_task
    result = _execute_callable(context=context, **execute_callable_kwargs)
             ^^^^^^^^^^^^^^^^^^^^^^^^^^^^^^^^^^^^^^^^^^^^^^^^^^^^^^^^^^^^^
  File "/home/airflow/.local/lib/python3.12/site-packages/airflow/models/taskinstance.py", line 733, in _execute_callable
    return ExecutionCallableRunner(
           ^^^^^^^^^^^^^^^^^^^^^^^^
  File "/home/airflow/.local/lib/python3.12/site-packages/airflow/utils/operator_helpers.py", line 252, in run
    return self.func(*args, **kwargs)
           ^^^^^^^^^^^^^^^^^^^^^^^^^^
  File "/home/airflow/.local/lib/python3.12/site-packages/airflow/models/baseoperator.py", line 417, in wrapper
    return func(self, *args, **kwargs)
           ^^^^^^^^^^^^^^^^^^^^^^^^^^^
  File "/home/airflow/.local/lib/python3.12/site-packages/airflow/operators/bash.py", line 257, in execute
    result = self._run_inline_command(bash_path=bash_path, env=env)
             ^^^^^^^^^^^^^^^^^^^^^^^^^^^^^^^^^^^^^^^^^^^^^^^^^^^^^^
  File "/home/airflow/.local/lib/python3.12/site-packages/airflow/operators/bash.py", line 284, in _run_inline_command
    return self.subprocess_hook.run_command(
           ^^^^^^^^^^^^^^^^^^^^^^^^^^^^^^^^^
  File "/home/airflow/.local/lib/python3.12/site-packages/airflow/hooks/subprocess.py", line 104, in run_command
    for raw_line in iter(self.sub_process.stdout.readline, b""):
                    ^^^^^^^^^^^^^^^^^^^^^^^^^^^^^^^^^^^^^^^^^^^
  File "/home/airflow/.local/lib/python3.12/site-packages/airflow/models/taskinstance.py", line 3095, in signal_handler
    raise AirflowTaskTerminated("Task received SIGTERM signal")
airflow.exceptions.AirflowTaskTerminated: Task received SIGTERM signal
[2024-11-22T10:09:51.020+0000] {taskinstance.py:1225} INFO - Marking task as UP_FOR_RETRY. dag_id=data_pipeline_etl, task_id=collect_data, run_id=scheduled__2024-11-22T00:00:00+00:00, execution_date=20241122T000000, start_date=20241122T093503, end_date=20241122T100951
[2024-11-22T10:09:51.039+0000] {taskinstance.py:340} INFO - ::group::Post task execution logs
[2024-11-22T10:09:51.078+0000] {process_utils.py:80} INFO - Process psutil.Process(pid=47, status='terminated', started='09:35:03') (47) terminated with exit code None
[2024-11-22T10:09:51.079+0000] {process_utils.py:80} INFO - Process psutil.Process(pid=45, status='terminated', exitcode=2, started='09:35:02') (45) terminated with exit code 2
[2024-11-22T10:09:51.080+0000] {local_task_job_runner.py:266} INFO - Task exited with return code 143
[2024-11-22T10:09:51.101+0000] {taskinstance.py:3895} INFO - 0 downstream tasks scheduled from follow-on schedule check
[2024-11-22T10:09:54.660+0000] {local_task_job_runner.py:123} INFO - ::group::Pre task execution logs
[2024-11-22T10:09:54.670+0000] {taskinstance.py:2603} INFO - Dependencies not met for <TaskInstance: data_pipeline_etl.collect_data scheduled__2024-11-22T00:00:00+00:00 [up_for_retry]>, dependency 'Not In Retry Period' FAILED: Task is not ready for retry yet but will be retried automatically. Current date is 2024-11-22T10:09:54.670791+00:00 and task will be retried at 2024-11-22T10:14:51.019914+00:00.
[2024-11-22T10:09:54.671+0000] {local_task_job_runner.py:166} INFO - Task is not able to be run
