[2024-11-24T13:27:07.056+0000] {local_task_job_runner.py:123} INFO - ::group::Pre task execution logs
[2024-11-24T13:27:07.066+0000] {taskinstance.py:2613} INFO - Dependencies all met for dep_context=non-requeueable deps ti=<TaskInstance: data_pipeline_etl.collect_data manual__2024-11-24T13:27:06.260515+00:00 [queued]>
[2024-11-24T13:27:07.070+0000] {taskinstance.py:2613} INFO - Dependencies all met for dep_context=requeueable deps ti=<TaskInstance: data_pipeline_etl.collect_data manual__2024-11-24T13:27:06.260515+00:00 [queued]>
[2024-11-24T13:27:07.070+0000] {taskinstance.py:2866} INFO - Starting attempt 1 of 2
[2024-11-24T13:27:07.077+0000] {taskinstance.py:2889} INFO - Executing <Task(BashOperator): collect_data> on 2024-11-24 13:27:06.260515+00:00
[2024-11-24T13:27:07.082+0000] {logging_mixin.py:190} WARNING - /home/***/.local/lib/python3.12/site-packages/***/task/task_runner/standard_task_runner.py:70 DeprecationWarning: This process (pid=172) is multi-threaded, use of fork() may lead to deadlocks in the child.
[2024-11-24T13:27:07.083+0000] {standard_task_runner.py:72} INFO - Started process 173 to run task
[2024-11-24T13:27:07.083+0000] {standard_task_runner.py:104} INFO - Running: ['***', 'tasks', 'run', 'data_pipeline_etl', 'collect_data', 'manual__2024-11-24T13:27:06.260515+00:00', '--job-id', '30', '--raw', '--subdir', 'DAGS_FOLDER/etl_pipeline_auto.py', '--cfg-path', '/tmp/tmpdu7fmbcd']
[2024-11-24T13:27:07.084+0000] {standard_task_runner.py:105} INFO - Job 30: Subtask collect_data
[2024-11-24T13:27:07.116+0000] {task_command.py:467} INFO - Running <TaskInstance: data_pipeline_etl.collect_data manual__2024-11-24T13:27:06.260515+00:00 [running]> on host 2bd538b8e0fb
[2024-11-24T13:27:07.166+0000] {taskinstance.py:3132} INFO - Exporting env vars: AIRFLOW_CTX_DAG_OWNER='***' AIRFLOW_CTX_DAG_ID='data_pipeline_etl' AIRFLOW_CTX_TASK_ID='collect_data' AIRFLOW_CTX_EXECUTION_DATE='2024-11-24T13:27:06.260515+00:00' AIRFLOW_CTX_TRY_NUMBER='1' AIRFLOW_CTX_DAG_RUN_ID='manual__2024-11-24T13:27:06.260515+00:00'
[2024-11-24T13:27:07.167+0000] {taskinstance.py:731} INFO - ::endgroup::
[2024-11-24T13:27:07.200+0000] {subprocess.py:78} INFO - Tmp dir root location: /tmp
[2024-11-24T13:27:07.201+0000] {subprocess.py:88} INFO - Running command: ['/usr/bin/bash', '-c', '/home/***/.local/bin/python /opt/***/data-pipeline-project/product_data_scraper.py']
[2024-11-24T13:27:07.207+0000] {subprocess.py:99} INFO - Output:
[2024-11-24T13:42:17.442+0000] {local_task_job_runner.py:127} ERROR - Received SIGTERM. Terminating subprocesses
[2024-11-24T13:42:17.459+0000] {process_utils.py:132} INFO - Sending 15 to group 173. PIDs of all processes in the group: [175, 173]
[2024-11-24T13:42:17.463+0000] {process_utils.py:87} INFO - Sending the signal 15 to group 173
[2024-11-24T13:42:17.466+0000] {taskinstance.py:3093} ERROR - Received SIGTERM. Terminating subprocesses.
[2024-11-24T13:42:17.477+0000] {subprocess.py:117} INFO - Sending SIGTERM signal to process group
[2024-11-24T13:42:17.516+0000] {taskinstance.py:3311} ERROR - Task failed with exception
Traceback (most recent call last):
  File "/home/airflow/.local/lib/python3.12/site-packages/airflow/models/taskinstance.py", line 762, in _execute_task
    result = _execute_callable(context=context, **execute_callable_kwargs)
             ^^^^^^^^^^^^^^^^^^^^^^^^^^^^^^^^^^^^^^^^^^^^^^^^^^^^^^^^^^^^^
  File "/home/airflow/.local/lib/python3.12/site-packages/airflow/models/taskinstance.py", line 733, in _execute_callable
    return ExecutionCallableRunner(
           ^^^^^^^^^^^^^^^^^^^^^^^^
  File "/home/airflow/.local/lib/python3.12/site-packages/airflow/utils/operator_helpers.py", line 252, in run
    return self.func(*args, **kwargs)
           ^^^^^^^^^^^^^^^^^^^^^^^^^^
  File "/home/airflow/.local/lib/python3.12/site-packages/airflow/models/baseoperator.py", line 417, in wrapper
    return func(self, *args, **kwargs)
           ^^^^^^^^^^^^^^^^^^^^^^^^^^^
  File "/home/airflow/.local/lib/python3.12/site-packages/airflow/operators/bash.py", line 257, in execute
    result = self._run_inline_command(bash_path=bash_path, env=env)
             ^^^^^^^^^^^^^^^^^^^^^^^^^^^^^^^^^^^^^^^^^^^^^^^^^^^^^^
  File "/home/airflow/.local/lib/python3.12/site-packages/airflow/operators/bash.py", line 284, in _run_inline_command
    return self.subprocess_hook.run_command(
           ^^^^^^^^^^^^^^^^^^^^^^^^^^^^^^^^^
  File "/home/airflow/.local/lib/python3.12/site-packages/airflow/hooks/subprocess.py", line 104, in run_command
    for raw_line in iter(self.sub_process.stdout.readline, b""):
                    ^^^^^^^^^^^^^^^^^^^^^^^^^^^^^^^^^^^^^^^^^^^
  File "/home/airflow/.local/lib/python3.12/site-packages/airflow/models/taskinstance.py", line 3095, in signal_handler
    raise AirflowTaskTerminated("Task received SIGTERM signal")
airflow.exceptions.AirflowTaskTerminated: Task received SIGTERM signal
[2024-11-24T13:42:17.525+0000] {taskinstance.py:1225} INFO - Marking task as UP_FOR_RETRY. dag_id=data_pipeline_etl, task_id=collect_data, run_id=manual__2024-11-24T13:27:06.260515+00:00, execution_date=20241124T132706, start_date=20241124T132707, end_date=20241124T134217
[2024-11-24T13:42:17.540+0000] {taskinstance.py:340} INFO - ::group::Post task execution logs
[2024-11-24T13:42:17.569+0000] {process_utils.py:80} INFO - Process psutil.Process(pid=175, status='terminated', started='13:27:06') (175) terminated with exit code None
[2024-11-24T13:42:17.570+0000] {process_utils.py:80} INFO - Process psutil.Process(pid=173, status='terminated', exitcode=2, started='13:27:06') (173) terminated with exit code 2
[2024-11-24T13:42:17.570+0000] {local_task_job_runner.py:266} INFO - Task exited with return code 143
[2024-11-24T13:42:17.585+0000] {taskinstance.py:3895} INFO - 0 downstream tasks scheduled from follow-on schedule check
[2024-11-24T13:42:17.657+0000] {standard_task_runner.py:217} INFO - Process not found (most likely exited), stop collecting metrics
