[2024-11-24T13:20:03.822+0000] {local_task_job_runner.py:123} INFO - ::group::Pre task execution logs
[2024-11-24T13:20:03.835+0000] {taskinstance.py:2613} INFO - Dependencies all met for dep_context=non-requeueable deps ti=<TaskInstance: data_pipeline_etl.collect_data manual__2024-11-24T13:20:02.718245+00:00 [queued]>
[2024-11-24T13:20:03.840+0000] {taskinstance.py:2613} INFO - Dependencies all met for dep_context=requeueable deps ti=<TaskInstance: data_pipeline_etl.collect_data manual__2024-11-24T13:20:02.718245+00:00 [queued]>
[2024-11-24T13:20:03.840+0000] {taskinstance.py:2866} INFO - Starting attempt 1 of 2
[2024-11-24T13:20:03.851+0000] {taskinstance.py:2889} INFO - Executing <Task(BashOperator): collect_data> on 2024-11-24 13:20:02.718245+00:00
[2024-11-24T13:20:03.856+0000] {logging_mixin.py:190} WARNING - /home/***/.local/lib/python3.12/site-packages/***/task/task_runner/standard_task_runner.py:70 DeprecationWarning: This process (pid=173) is multi-threaded, use of fork() may lead to deadlocks in the child.
[2024-11-24T13:20:03.857+0000] {standard_task_runner.py:72} INFO - Started process 174 to run task
[2024-11-24T13:20:03.856+0000] {standard_task_runner.py:104} INFO - Running: ['***', 'tasks', 'run', 'data_pipeline_etl', 'collect_data', 'manual__2024-11-24T13:20:02.718245+00:00', '--job-id', '28', '--raw', '--subdir', 'DAGS_FOLDER/etl_pipeline_auto.py', '--cfg-path', '/tmp/tmpnuz7kt1n']
[2024-11-24T13:20:03.858+0000] {standard_task_runner.py:105} INFO - Job 28: Subtask collect_data
[2024-11-24T13:20:03.889+0000] {task_command.py:467} INFO - Running <TaskInstance: data_pipeline_etl.collect_data manual__2024-11-24T13:20:02.718245+00:00 [running]> on host 12b36524d4ff
[2024-11-24T13:20:03.938+0000] {taskinstance.py:3132} INFO - Exporting env vars: AIRFLOW_CTX_DAG_OWNER='***' AIRFLOW_CTX_DAG_ID='data_pipeline_etl' AIRFLOW_CTX_TASK_ID='collect_data' AIRFLOW_CTX_EXECUTION_DATE='2024-11-24T13:20:02.718245+00:00' AIRFLOW_CTX_TRY_NUMBER='1' AIRFLOW_CTX_DAG_RUN_ID='manual__2024-11-24T13:20:02.718245+00:00'
[2024-11-24T13:20:03.939+0000] {taskinstance.py:731} INFO - ::endgroup::
[2024-11-24T13:20:03.972+0000] {subprocess.py:78} INFO - Tmp dir root location: /tmp
[2024-11-24T13:20:03.973+0000] {subprocess.py:88} INFO - Running command: ['/usr/bin/bash', '-c', '/home/***/.local/bin/python /opt/***/data-pipeline-project/product_data_scraper.py']
[2024-11-24T13:20:03.978+0000] {subprocess.py:99} INFO - Output:
[2024-11-24T13:26:08.913+0000] {local_task_job_runner.py:127} ERROR - Received SIGTERM. Terminating subprocesses
[2024-11-24T13:26:08.950+0000] {process_utils.py:132} INFO - Sending 15 to group 174. PIDs of all processes in the group: [176, 174]
[2024-11-24T13:26:08.955+0000] {process_utils.py:87} INFO - Sending the signal 15 to group 174
[2024-11-24T13:26:08.963+0000] {taskinstance.py:3093} ERROR - Received SIGTERM. Terminating subprocesses.
[2024-11-24T13:26:08.970+0000] {subprocess.py:117} INFO - Sending SIGTERM signal to process group
[2024-11-24T13:26:08.998+0000] {taskinstance.py:3311} ERROR - Task failed with exception
Traceback (most recent call last):
  File "/home/airflow/.local/lib/python3.12/site-packages/airflow/models/taskinstance.py", line 762, in _execute_task
    result = _execute_callable(context=context, **execute_callable_kwargs)
             ^^^^^^^^^^^^^^^^^^^^^^^^^^^^^^^^^^^^^^^^^^^^^^^^^^^^^^^^^^^^^
  File "/home/airflow/.local/lib/python3.12/site-packages/airflow/models/taskinstance.py", line 733, in _execute_callable
    return ExecutionCallableRunner(
           ^^^^^^^^^^^^^^^^^^^^^^^^
  File "/home/airflow/.local/lib/python3.12/site-packages/airflow/utils/operator_helpers.py", line 252, in run
    return self.func(*args, **kwargs)
           ^^^^^^^^^^^^^^^^^^^^^^^^^^
  File "/home/airflow/.local/lib/python3.12/site-packages/airflow/models/baseoperator.py", line 417, in wrapper
    return func(self, *args, **kwargs)
           ^^^^^^^^^^^^^^^^^^^^^^^^^^^
  File "/home/airflow/.local/lib/python3.12/site-packages/airflow/operators/bash.py", line 257, in execute
    result = self._run_inline_command(bash_path=bash_path, env=env)
             ^^^^^^^^^^^^^^^^^^^^^^^^^^^^^^^^^^^^^^^^^^^^^^^^^^^^^^
  File "/home/airflow/.local/lib/python3.12/site-packages/airflow/operators/bash.py", line 284, in _run_inline_command
    return self.subprocess_hook.run_command(
           ^^^^^^^^^^^^^^^^^^^^^^^^^^^^^^^^^
  File "/home/airflow/.local/lib/python3.12/site-packages/airflow/hooks/subprocess.py", line 104, in run_command
    for raw_line in iter(self.sub_process.stdout.readline, b""):
                    ^^^^^^^^^^^^^^^^^^^^^^^^^^^^^^^^^^^^^^^^^^^
  File "/home/airflow/.local/lib/python3.12/site-packages/airflow/models/taskinstance.py", line 3095, in signal_handler
    raise AirflowTaskTerminated("Task received SIGTERM signal")
airflow.exceptions.AirflowTaskTerminated: Task received SIGTERM signal
[2024-11-24T13:26:09.030+0000] {taskinstance.py:1225} INFO - Marking task as UP_FOR_RETRY. dag_id=data_pipeline_etl, task_id=collect_data, run_id=manual__2024-11-24T13:20:02.718245+00:00, execution_date=20241124T132002, start_date=20241124T132003, end_date=20241124T132609
[2024-11-24T13:26:09.045+0000] {taskinstance.py:340} INFO - ::group::Post task execution logs
[2024-11-24T13:26:09.062+0000] {process_utils.py:80} INFO - Process psutil.Process(pid=176, status='terminated', started='13:20:02') (176) terminated with exit code None
[2024-11-24T13:26:09.062+0000] {process_utils.py:80} INFO - Process psutil.Process(pid=174, status='terminated', exitcode=2, started='13:20:02') (174) terminated with exit code 2
[2024-11-24T13:26:09.063+0000] {local_task_job_runner.py:266} INFO - Task exited with return code 143
[2024-11-24T13:26:09.077+0000] {taskinstance.py:3895} INFO - 0 downstream tasks scheduled from follow-on schedule check
[2024-11-24T13:26:09.078+0000] {standard_task_runner.py:217} INFO - Process not found (most likely exited), stop collecting metrics
